Workbook

Sheet horarios BBDD
A1: Horario | B1: Horas
A2: 10:00 - 16:00 | B2: 6
A3: 10:00 - 15:00 y 16:00 - 20:00 | B3: 9
A4: LIBRE | B4: 0
A5: 10:00 - 15:00 | B5: 5
A6: 11:00 - 15:00 y 16:00 - 20:00 | B6: 8
A7: 11:00 - 14:00 y 16:00 - 22:00 | B7: 9
A8: 11:00 - 15:00 | B8: 4
A9: 16:00 - 21:00 | B9: 5
A10: 11:00 - 14:00 Y 16:00 - 21:00 | B10: 8
A11: 10:00 - 14:00 y 17:00 - 21:00 | B11: 8
A12: 16:00 - 20:00 | B12: 4
A13: 17:00 - 21:00 | B13: 4
... A78: 10:30 - 13:30 y 16:00 - 21:00 | B78: 8

Sheet VACACIONES
F2: =CONCAT("W ",ISOWEEKNUM(F3)) -> W 40 | K2: =CONCAT("W ",ISOWEEKNUM(K3)) -> W 41 | R2: =CONCAT("W ",ISOWEEKNUM(R3)) -> W 42 | Y2: =CONCAT("W ",ISOWEEKNUM(Y3)) -> W 43 | AF2: =CONCAT("W ",ISOWEEKNUM(AF3)) -> W 44 | AM2: =CONCAT("W ",ISOWEEKNUM(AM3)) -> W 45 | AT2: =CONCAT("W ",ISOWEEKNUM(AT3)) -> W 46 | BA2: =CONCAT("W ",ISOWEEKNUM(BA3)) -> W 47 | BH2: =CONCAT("W ",ISOWEEKNUM(BH3)) -> W 48 | BO2: =CONCAT("W ",ISOWEEKNUM(BO3)) -> W 49 | BV2: =CONCAT("W ",ISOWEEKNUM(BV3)) -> W 50 | CC2: =CONCAT("W ",ISOWEEKNUM(CC3)) -> W 51 | CJ2: =CONCAT("W ",ISOWEEKNUM(CJ3)) -> W 52 | CQ2: =CONCAT("W ",ISOWEEKNUM(CQ3)) -> W 1
A3: CENTRO | B3: GPV | C3: HORAS | D3: Promotor | E3: Telefono | F3: 45931 | G3: 45932 | H3: 45933 | I3: 45934 | J3: 45935 | K3: 45936 | L3: 45937 | M3: 45938 | N3: 45939 | O3: 45940 | P3: 45941 | Q3: 45942 | R3: 45943 | S3: 45944 | T3: 45945 | U3: 45946 | V3: 45947 | W3: 45948 | X3: 45949 | Y3: 45950 | Z3: 45951 | AA3: 45952 | AB3: 45953 | AC3: 45954 | AD3: 45955 | AE3: 45956 | AF3: 45957 | AG3: 45958 | AH3: 45959 | AI3: 45960 | AJ3: 45961 | AK3: 45962 | AL3: 45963 | AM3: 45964 | AN3: 45965 | AO3: 45966 | AP3: 45967 | AQ3: 45968 | AR3: 45969 | AS3: 45970 | AT3: 45971 | AU3: 45972 | AV3: 45973 | AW3: 45974 | AX3: 45975 | AY3: 45976 | AZ3: 45977 | BA3: 45978 | BB3: 45979 | BC3: 45980 | BD3: 45981 | BE3: 45982 | BF3: 45983 | BG3: 45984 | BH3: 45985 | BI3: 45986 | BJ3: 45987 | BK3: 45988 | BL3: 45989 | BM3: 45990 | BN3: 45991 | BO3: 45992 | BP3: 45993 | BQ3: 45994 | BR3: 45995 | BS3: 45996 | BT3: 45997 | BU3: 45998 | BV3: 45999 | BW3: 46000 | BX3: 46001 | BY3: 46002 | BZ3: 46003 | CA3: 46004 | CB3: 46005 | CC3: 46006 | CD3: 46007 | CE3: 46008 | CF3: 46009 | CG3: 46010 | CH3: 46011 | CI3: 46012 | CJ3: 46013 | CK3: 46014 | CL3: 46015 | CM3: 46016 | CN3: 46017 | CO3: 46018 | CP3: 46019 | CQ3: 46020 | CR3: 46021 | CS3: 46022
A4: ECI CORNELLÁ | C4: 40 | D4: ABRIL | E4: 696240297
A5: ECI PLAZA DEL DUQUE | C5: 40 | D5: CLARIBEL | E5: 648707154
A6: ECI RONDA CÓRDOBA | C6: 40 | D6: MIGUEL | E6: 619911709
A7: ECI ÁLCALA DE HENARES | C7: 40 | D7: NOELIA
A8: ECI A CORUÑA | C8: 40 | D8: ALEJANDRO | E8: 609124351
A9: ECI HUELVA | C9: 40 | D9: MARIO | E9: 616238557
A10: ECI LEÓN | C10: 40 | D10: GRACIELA | E10: 669910323
A11: ECI SALAMANCA | C11: 40 | D11: ALISON | E11: 660956572
A12: ECI SAN JOSÉ DE VALDERAS | C12: 40 | D12: ZEVALLOS | E12: 620482634
A13: ECI BAHÍA MÁLAGA | C13: 40 | D13: DAVID | E13: 669748156
A14: ECI COSTA MIJAS | C14: 40 | D14: CARLOS | E14: 689765147
A15: ECI ZARAGOZA ( SAGASTA) | C15: 40 | D15: ESTELA | E15: 669069016
A16: ECI PAMPLONA | C16: 40 | D16: ANNE | E16: 604216203
A17: ECI TALAVERA | C17: 40 | D17: LAURA | E17: 636617230
A18: ECI GUADALAJARA | C18: 40 | D18: DARWIN | E18: 680820970
C19: 40 | E19: 660956572
C20: 40 | E20: 679755778
C21: 40 | E21: 649829706
C22: 40 | E22: 676986157
C23: 40 | E23: 639365901
C24: 40 | E24: 691224926
C25: 40 | E25: 608183544
C26: 40 | E26: 630200841
C27: 40 | E27: 648703793
C28: 40 | E28: 638770422
C29: 40 | E29: 682535258
C30: 40 | E30: 638056966
... C34: 40 | E34: 630412945
C35: 40
C36: 40 | E36: 680396554
C37: 40 | E37: 638099194
C38: 40 | E38: 656408637
C39: 40 | E39: 630467357
C40: 40 | E40: 608418184
C41: 40 | E41: 686844158
C42: 40 | E42: 689441653
C43: 40 | E43: 636675598
C44: 40

Sheet incidencias W45
A3: CENTRO | B3: Promotor | C3: Lunes | F3: Martes | I3: Miercoles | L3: Jueves | O3: Viernes | R3: Sabado | U3: Domingo | X3: total
A4: ECI CORNELLÁ | B4: ABRIL | C4: LIBRE | D4: 0 | F4: 12:00 - 14:00 y 15:00 - 21:00 | G4: 8 | I4: 12:00 - 14:00 y 15:00 - 21:00 | J4: 8 | L4: 12:00 - 14:00 y 15:00 - 21:00 | M4: 8 | O4: 12:00 - 14:00 y 15:00 - 21:00 | P4: 8 | R4: 12:00 - 14:00 y 15:00 - 21:00 | S4: 8 | U4: LIBRE | V4: 0 | X4: 40
A5: ECI PLAZA DEL DUQUE | B5: CLARIBEL | C5: LIBRE | D5: 0 | F5: 12:00 - 14:00 y 15:00 - 21:00 | G5: 8 | I5: 12:00 - 14:00 y 15:00 - 21:00 | J5: 8 | L5: 12:00 - 14:00 y 15:00 - 21:00 | M5: 8 | O5: 12:00 - 14:00 y 15:00 - 21:00 | P5: 8 | R5: 12:00 - 14:00 y 15:00 - 21:00 | S5: 8 | U5: LIBRE | V5: 0 | X5: 40
A6: ECI RONDA CÓRDOBA | B6: MIGUEL | C6: LIBRE | D6: 0 | F6: 12:00 - 15:00 y 16:00 - 21:00 | G6: 8 | I6: 12:00 - 15:00 y 16:00 - 21:00 | J6: 8 | L6: 12:00 - 15:00 y 16:00 - 21:00 | M6: 8 | O6: 12:00 - 15:00 y 16:00 - 21:00 | P6: 8 | R6: 12:00 - 15:00 y 16:00 - 21:00 | S6: 8 | U6: LIBRE | V6: 0 | X6: 40
A7: ECI ÁLCALA DE HENARES | B7: NOELIA | C7: LIBRE | D7: 0 | F7: LIBRE | G7: 0 | I7: 12:00 - 14:00 y 15:00 - 21:00 | J7: 8 | L7: 12:00 - 14:00 y 15:00 - 21:00 | M7: 8 | O7: 12:00 - 14:00 y 15:00 - 21:00 | P7: 8 | R7: 12:00 - 14:00 y 15:00 - 21:00 | S7: 8 | U7: 12:00 - 14:00 y 15:00 - 21:00 | V7: 8 | X7: 40
A8: ECI A CORUÑA | B8: ALEJANDRO | C8: 12:00 - 14:00 y 15:00 - 21:00 | D8: 8 | F8: 12:00 - 14:00 y 15:00 - 21:00 | G8: 8 | I8: LIBRE | J8: 0 | L8: 12:00 - 14:00 y 15:00 - 21:00 | M8: 8 | O8: 12:00 - 14:00 y 15:00 - 21:00 | P8: 8 | R8: 12:00 - 14:00 y 15:00 - 21:00 | S8: 8 | U8: LIBRE | V8: 0 | X8: 40
A9: ECI HUELVA | B9: MARIO | C9: 10:30 - 13:30 y 16:00 - 21:00 | D9: 8 | F9: 10:30 - 13:30 y 16:00 - 21:00 | G9: 8 | I9: LIBRE | J9: 0 | L9: 10:30 - 13:30 y 16:00 - 21:00 | M9: 8 | O9: 10:00 - 14:00 y 17:00 - 21:00 | P9: 8 | R9: 10:00 - 14:00 y 17:00 - 21:00 | S9: 8 | U9: LIBRE | V9: 0 | X9: 40
A10: ECI LEÓN | B10: GRACIELA | C10: 12:00 - 14:00 y 15:00 - 21:00 | D10: 8 | F10: 12:00 - 14:00 y 15:00 - 21:00 | G10: 8 | I10: LIBRE | J10: 0 | L10: 12:00 - 14:00 y 15:00 - 21:00 | M10: 8 | O10: 12:00 - 14:00 y 15:00 - 21:00 | P10: 8 | R10: 12:00 - 14:00 y 15:00 - 21:00 | S10: 8 | U10: LIBRE | V10: 0 | X10: 40
A11: ECI SALAMANCA | B11: ALISON | C11: 12:00 - 14:00 y 15:00 - 21:00 | D11: 8 | F11: 12:00 - 14:00 y 15:00 - 21:00 | G11: 8 | I11: LIBRE | J11: 0 | L11: 12:00 - 14:00 y 15:00 - 21:00 | M11: 8 | O11: 12:00 - 14:00 y 15:00 - 21:00 | P11: 8 | R11: 12:00 - 14:00 y 15:00 - 21:00 | S11: 8 | U11: LIBRE | V11: 0 | X11: 40
A12: ECI SAN JOSÉ DE VALDERAS | B12: ZEVALLOS | C12: LIBRE | D12: 0 | F12: LIBRE | G12: 0 | I12: 12:00 - 15:00 y 16:00 - 21:00 | J12: 8 | L12: 12:00 - 15:00 y 16:00 - 21:00 | M12: 8 | O12: 12:00 - 15:00 y 16:00 - 21:00 | P12: 8 | R12: 12:00 - 15:00 y 16:00 - 21:00 | S12: 8 | U12: 12:00 - 15:00 y 16:00 - 21:00 | V12: 8 | X12: 40
A13: ECI BAHÍA MÁLAGA | B13: DAVID | C13: 12:00 - 14:00 y 15:00 - 21:00 | D13: 8 | F13: LIBRE | G13: 0 | I13: 12:00 - 14:00 y 15:00 - 21:00 | J13: 8 | L13: 12:00 - 14:00 y 15:00 - 21:00 | M13: 8 | O13: 12:00 - 14:00 y 15:00 - 21:00 | P13: 8 | R13: 12:00 - 14:00 y 15:00 - 21:00 | S13: 8 | U13: LIBRE | V13: 0 | X13: 40
A14: ECI COSTA MIJAS | B14: BRYAN | C14: LIBRE | D14: 0 | F14: 12:00 - 14:00 y 15:00 - 21:00 | G14: 8 | I14: 12:00 - 14:00 y 15:00 - 21:00 | J14: 8 | L14: 12:00 - 14:00 y 15:00 - 21:00 | M14: 8 | O14: 12:00 - 14:00 y 15:00 - 21:00 | P14: 8 | R14: 12:00 - 14:00 y 15:00 - 21:00 | S14: 8 | U14: LIBRE | V14: 0 | X14: 40
A15: ECI ZARAGOZA ( SAGASTA) | B15: ESTELA | C15: 12:00 - 14:00 y 15:00 - 21:00 | D15: 8 | F15: LIBRE | G15: 0 | I15: 12:00 - 14:00 y 15:00 - 21:00 | J15: 8 | L15: 12:00 - 14:00 y 15:00 - 21:00 | M15: 8 | O15: 12:00 - 14:00 y 15:00 - 21:00 | P15: 8 | R15: 12:00 - 14:00 y 15:00 - 21:00 | S15: 8 | U15: LIBRE | V15: 0 | X15: 40
... A18: ECI GUADALAJARA | B18: DARVIN | C18: 12:00 - 14:00 y 15:00 - 21:00 | D18: 8 | F18: LIBRE | G18: 0 | I18: 12:00 - 14:00 y 15:00 - 21:00 | J18: 8 | L18: 12:00 - 14:00 y 15:00 - 21:00 | M18: 8 | O18: 12:00 - 14:00 y 15:00 - 21:00 | P18: 8 | R18: 12:00 - 14:00 y 15:00 - 21:00 | S18: 8 | U18: LIBRE | V18: 0 | X18: 40
A22: CENTRO | B22: Promotor | C22: Lunes 03 | F22: Martes 04 | I22: Miercoles 05 | L22: Jueves 06 | O22: Viernes 07 | R22: Sabado 08 | U22: Domingo 09 | X22: total
A23: ECI LEÓN | B23: GRACIELA | C23: 12:00 - 14:00 y 15:00 - 21:00 | D23: 8 | E23: Mesa rota, entró sin demos | F23: 12:00 - 14:00 y 15:00 - 21:00 | G23: 8 | H23: Demos en mesa repetidos x2 magic 7lite y x2 magic PAD 2/ Demo X5C falta | I23: LIBRE | J23: 0 | L23: 12:00 - 14:00 y 15:00 - 21:00 | M23: 8 | O23: 12:00 - 14:00 y 15:00 - 21:00 | P23: 8 | R23: 12:00 - 14:00 y 15:00 - 21:00 | S23: 8 | U23: LIBRE | V23: 0 | X23: 40
A24: ECI SALAMANCA | B24: ALISON | C24: 12:00 - 14:00 y 15:00 - 21:00 | D24: 8 | E24: Perdida de venta por no tener demo X5C | F24: 12:00 - 14:00 y 15:00 - 21:00 | G24: 8 | I24: LIBRE | J24: 0 | L24: 12:00 - 14:00 y 15:00 - 21:00 | M24: 8 | O24: 12:00 - 14:00 y 15:00 - 21:00 | P24: 8 | R24: 12:00 - 14:00 y 15:00 - 21:00 | S24: 8 | U24: LIBRE | V24: 0 | X24: 40
A25: ECI BAHÍA MÁLAGA | B25: DAVID | C25: 12:00 - 14:00 y 15:00 - 21:00 | D25: 8 | E25: Demos en mesa repetidos x2 magic 7lite y x2 magic PAD 2/ Demo X5C falta | F25: LIBRE | G25: 0 | I25: 12:00 - 14:00 y 15:00 - 21:00 | J25: 8 | K25: PIERDE VENTAS POR NO TENER STOCK DE MAGICPAD2 | L25: 12:00 - 14:00 y 15:00 - 21:00 | M25: 8 | O25: 12:00 - 14:00 y 15:00 - 21:00 | P25: 8 | R25: 12:00 - 14:00 y 15:00 - 21:00 | S25: 8 | U25: LIBRE | V25: 0 | X25: 40
A26: ECI COSTA MIJAS | B26: BRYAN | C26: LIBRE | D26: 0 | F26: 12:00 - 14:00 y 15:00 - 21:00 | G26: 8 | H26: Demos en mesa repetidos x2 magic 7lite y x2 magic PAD 2/ Demo X5C falta | I26: 12:00 - 14:00 y 15:00 - 21:00 | J26: 8 | K26: Vende X5C SIN DEMO | L26: 12:00 - 14:00 y 15:00 - 21:00 | M26: 8 | O26: 12:00 - 14:00 y 15:00 - 21:00 | P26: 8 | R26: 12:00 - 14:00 y 15:00 - 21:00 | S26: 8 | T26: PANTALLAS MESA APAGADAS | U26: LIBRE | V26: 0 | X26: 40
A27: ECI CORNELLÁ | B27: ABRIL | D27: 0 | F27: 12:00 - 14:00 y 15:00 - 21:00 | G27: 8 | H27: Falta stock H400 Pro / Escalerilla apagada / Demo X5C falta | I27: 12:00 - 14:00 y 15:00 - 21:00 | J27: 8 | K27: SIGUE CON LA ESCALERILLA APAGADA | L27: 12:00 - 14:00 y 15:00 - 21:00 | M27: 8 | N27: ALERTA PROTECCIÓN CIVIL | O27: 12:00 - 14:00 y 15:00 - 21:00 | P27: 8 | Q27: PIERDE VENTA POR FALTA DE STOCK 400 DESERT GOLD | R27: 12:00 - 14:00 y 15:00 - 21:00 | S27: 8 | T27: PIERDE VENTA DE X2 V5 POR TENER DEMO | U27: LIBRE | V27: 0 | X27: 40
A28: ECI RONDA CÓRDOBA | B28: MIGUEL | D28: 0 | G28: 8 | I28: 12:00 - 15:00 y 16:00 - 21:00 | J28: 8 | K28: MESA SIN CORRIENTE/ ALERTA NARANJA | L28: 12:00 - 15:00 y 16:00 - 21:00 | M28: 8 | N28: MESA SIN CORRIENTE/ ALERTA NARANJA | O28: 12:00 - 15:00 y 16:00 - 21:00 | P28: 8 | R28: 12:00 - 15:00 y 16:00 - 21:00 | S28: 8 | U28: LIBRE | V28: 0 | X28: 40
A29: ECI ÁLCALA DE HENARES | B29: NOELIA | D29: 0 | G29: 0 | I29: 12:00 - 14:00 y 15:00 - 21:00 | J29: 8 | K29: HONOR 400 SIN STOCK PIERDE VENTA | L29: 12:00 - 14:00 y 15:00 - 21:00 | M29: 8 | O29: 12:00 - 14:00 y 15:00 - 21:00 | P29: 8 | R29: 12:00 - 14:00 y 15:00 - 21:00 | S29: 8 | U29: LIBRE | V29: 8 | W29: LIBRA POR TEMAS PERSONALES ANTES DE LA INCORPORACIÓN | X29: 40
A30: ECI SAN JOSÉ DE VALDERAS | B30: ZEVALLOS | D30: 0 | G30: 0 | I30: 12:00 - 15:00 y 16:00 - 21:00 | J30: 8 | K30: PIERDE VENTA POR NO TENER STOCK MAGIC 7LITE 256GB/ H400/ FALTA DE DEMOS X5C | L30: 12:00 - 15:00 y 16:00 - 21:00 | M30: 8 | N30: FALTA DE CONOCIMIENTOS POR PARTE DE ECI SOBRE LA MARCA, NO TIENEN CONFIANZA | O30: 12:00 - 15:00 y 16:00 - 21:00 | P30: 8 | Q30: PIERDE VENTA POR FALTA DE STOCK 400 | R30: 12:00 - 15:00 y 16:00 - 21:00 | S30: 8 | U30: 12:00 - 15:00 y 16:00 - 21:00 | V30: 0 | X30: 40
A31: ECI TALAVERA | B31: LAURA | D31: 8 | G31: 8 | I31: LIBRE | J31: 0 | L31: 12:00 - 14:00 y 15:00 - 21:00 | M31: 8 | N31: NO ENTRA PORQUE NO ESTA LA TIENDA MONTADA | O31: 12:00 - 14:00 y 15:00 - 21:00 | P31: 8 | R31: 12:00 - 14:00 y 15:00 - 21:00 | S31: 8 | U31: LIBRE | V31: 0 | X31: 40
A32: ECI GUADALAJARA | B32: DARWIN | D32: 8 | G32: 0 | I32: 12:00 - 14:00 y 15:00 - 21:00 | J32: 8 | K32: ENTRA SIN MESA NI ESCALERILLAS | L32: 12:00 - 14:00 y 15:00 - 21:00 | M32: 8 | O32: 12:00 - 14:00 y 15:00 - 21:00 | P32: 8 | R32: 12:00 - 14:00 y 15:00 - 21:00 | S32: 8 | U32: LIBRE | V32: 0 | X32: 40
A33: ECI PLAZA DEL DUQUE | B33: CLARIBEL | D33: 0 | G33: 8 | J33: 8 | M33: 8 | O33: 12:00 - 14:00 y 15:00 - 21:00 | P33: 8 | R33: 12:00 - 14:00 y 15:00 - 21:00 | S33: 8 | U33: LIBRE | V33: 0 | X33: 40
A34: ECI A CORUÑA | B34: ALEJANDRO | D34: 8 | G34: 8 | J34: 0 | M34: 8 | O34: 12:00 - 14:00 y 15:00 - 21:00 | P34: 8 | R34: 12:00 - 14:00 y 15:00 - 21:00 | S34: 8 | U34: LIBRE | V34: 0 | X34: 40
A35: ECI HUELVA | B35: MARIO | D35: 8 | G35: 8 | J35: 0 | M35: 8 | O35: 10:00 - 14:00 y 17:00 - 21:00 | P35: 8 | R35: 10:00 - 14:00 y 17:00 - 21:00 | S35: 8 | U35: LIBRE | V35: 0 | X35: 40
A36: ECI ZARAGOZA ( SAGASTA) | B36: ESTELA | D36: 8 | G36: 0 | J36: 8 | M36: 8 | O36: 12:00 - 14:00 y 15:00 - 21:00 | P36: 8 | Q36: SIN CORRIENTE EN LA MESA | R36: 12:00 - 14:00 y 15:00 - 21:00 | S36: 8 | U36: LIBRE | V36: 0 | X36: 40
A37: ECI PAMPLONA | B37: ANNE | D37: 8 | G37: 0 | J37: 8 | M37: 8 | O37: 11:00 - 14:00 y 16:00 - 21:00 | P37: 8 | R37: 11:00 - 14:00 y 16:00 - 21:00 | S37: 8 | U37: LIBRE | V37: 0 | X37: 40

Sheet BF horarios
A1: W48
A2: CENTRO | B2: Lunes | D2: Martes | F2: Miercoles | H2: Jueves | J2: Viernes | L2: Sabado | N2: Domingo | P2: total | Q2: Comentarios
A3: ECI LEÓN | B3: 12:00 - 14:00 y 15:00 - 21:00 | C3: 8 | D3: 12:00 - 14:00 y 15:00 - 21:00 | E3: 8 | F3: LIBRE | G3: 0 | H3: 12:00 - 14:00 y 15:00 - 21:00 | I3: 8 | J3: 12:00 - 14:00 y 15:00 - 21:00 | K3: 8 | L3: 12:00 - 14:00 y 15:00 - 21:00 | M3: 8 | N3: LIBRE | O3: 0 | P3: =SUM(C3+E3+G3+I3+K3+M3+O3) -> 40
A4: ECI COSTA MIJAS | B4: LIBRE | C4: 0 | D4: LIBRE | E4: 0 | F4: 12:00 - 14:00 y 15:00 - 21:00 | G4: 8 | H4: 12:00 - 14:00 y 15:00 - 21:00 | I4: 8 | J4: 12:00 - 14:00 y 15:00 - 21:00 | K4: 8 | L4: 12:00 - 14:00 y 15:00 - 21:00 | M4: 8 | N4: 12:00 - 15:00 y 16:00 - 21:00 | O4: 8 | P4: =SUM(C4+E4+G4+I4+K4+M4+O4) -> 40
A5: ECI BAHÍA MÁLAGA | B5: LIBRE | C5: 0 | D5: 11:00 - 14:00 y 16:00 - 21:00 | E5: 8 | F5: 11:00 - 14:00 y 16:00 - 21:00 | G5: 8 | H5: 11:00 - 14:00 y 16:00 - 21:00 | I5: 8 | J5: 11:00 - 14:00 y 16:00 - 21:00 | K5: 8 | L5: 11:00 - 14:00 y 16:00 - 21:00 | M5: 8 | N5: 11:00 - 14:00 y 16:00 - 21:00 | O5: 8 | P5: =SUM(C5+E5+G5+I5+K5+M5+O5) -> 48
A6: ECI CORNELLÁ | B6: 12:00 - 14:00 y 15:00 - 21:00 | C6: 8 | D6: 12:00 - 14:00 y 15:00 - 21:00 | E6: 8 | F6: 12:00 - 14:00 y 15:00 - 21:00 | G6: 8 | H6: 12:00 - 14:00 y 15:00 - 21:00 | I6: 8 | J6: 12:00 - 14:00 y 15:00 - 21:00 | K6: 8 | L6: 12:00 - 14:00 y 15:00 - 21:00 | M6: 8 | N6: LIBRE | O6: 0 | P6: =SUM(C6+E6+G6+I6+K6+M6+O6) -> 48
A7: ECI PLAZA DEL DUQUE | B7: LIBRE | C7: 0 | D7: 12:00 - 14:00 y 15:00 - 21:00 | E7: 8 | F7: 12:00 - 14:00 y 15:00 - 21:00 | G7: 8 | H7: 12:00 - 14:00 y 15:00 - 21:00 | I7: 8 | J7: 12:00 - 14:00 y 15:00 - 21:00 | K7: 8 | L7: 12:00 - 14:00 y 15:00 - 21:00 | M7: 8 | N7: 12:00 - 14:00 y 15:00 - 21:00 | O7: 8 | P7: =SUM(C7+E7+G7+I7+K7+M7+O7) -> 48 | Q7: Tiene médico a las 12:00, (26/11/25)
A8: ECI TALAVERA | B8: 12:00 - 14:00 y 15:00 - 21:00 | C8: 8 | D8: LIBRE | E8: 0 | F8: 12:00 - 14:00 y 15:00 - 21:00 | G8: 0 | H8: 12:00 - 14:00 y 15:00 - 21:00 | I8: 8 | J8: 12:00 - 14:00 y 15:00 - 21:00 | K8: 8 | L8: 12:00 - 14:00 y 15:00 - 21:00 | M8: 8 | N8: 12:00 - 14:00 y 15:00 - 21:00 | O8: 8 | P8: =SUM(C8+E8+G8+I8+K8+M8+O8) -> 40
A9: ECI ZARAGOZA ( SAGASTA) | B9: 12:00 - 14:00 y 15:00 - 21:00 | C9: 8 | D9: LIBRE | E9: 0 | F9: 12:00 - 14:00 y 15:00 - 21:00 | G9: 8 | H9: 12:00 - 14:00 y 15:00 - 21:00 | I9: 8 | J9: 12:00 - 14:00 y 15:00 - 21:00 | K9: 8 | L9: 12:00 - 14:00 y 15:00 - 21:00 | M9: 8 | N9: 12:00 - 15:00 y 16:00 - 21:00 | O9: 8 | P9: =SUM(C9+E9+G9+I9+K9+M9+O9) -> 48
A10: ECI ÁLCALA DE HENARES | B10: LIBRE | C10: 0 | D10: 12:00 - 14:00 y 15:00 - 21:00 | E10: 0 | F10: 12:00 - 14:00 y 15:00 - 21:00 | G10: 8 | H10: 12:00 - 14:00 y 15:00 - 21:00 | I10: 8 | J10: 12:00 - 14:00 y 15:00 - 21:00 | K10: 8 | L10: 12:00 - 14:00 y 15:00 - 21:00 | M10: 8 | N10: 12:00 - 14:00 y 15:00 - 21:00 | O10: 8 | P10: =SUM(C10+E10+G10+I10+K10+M10+O10) -> 40
A11: ECI RONDA CÓRDOBA | B11: 12:00 - 15:00 y 16:00 - 21:00 | C11: 8 | D11: 12:00 - 15:00 y 16:00 - 21:00 | E11: 8 | F11: 12:00 - 15:00 y 16:00 - 21:00 | G11: 5 | H11: 12:00 - 15:00 y 16:00 - 21:00 | I11: 8 | J11: 12:00 - 15:00 y 16:00 - 21:00 | K11: 8 | L11: 12:00 - 15:00 y 16:00 - 21:00 | M11: 8 | N11: LIBRE | O11: 0 | P11: =SUM(C11+E11+G11+I11+K11+M11+O11) -> 45
A12: ECI SALAMANCA | B12: 12:00 - 14:00 y 15:00 - 21:00 | C12: 8 | D12: 12:00 - 14:00 y 15:00 - 21:00 | E12: 8 | F12: 12:00 - 14:00 y 15:00 - 21:00 | G12: 8 | H12: 12:00 - 14:00 y 15:00 - 21:00 | I12: 8 | J12: 12:00 - 14:00 y 15:00 - 21:00 | K12: 8 | L12: 12:00 - 14:00 y 15:00 - 21:00 | M12: 8 | N12: LIBRE | O12: 0 | P12: =SUM(C12+E12+G12+I12+K12+M12+O12) -> 48
A13: ECI GUADALAJARA | B13: 12:00 - 14:00 y 15:00 - 21:00 | C13: 8 | D13: 12:00 - 14:00 y 15:00 - 21:00 | E13: 8 | F13: 12:00 - 14:00 y 15:00 - 21:00 | G13: 8 | H13: 12:00 - 14:00 y 15:00 - 21:00 | I13: 8 | J13: 11:00 - 14:00 y 16:00 - 21:00 | K13: 8 | L13: 11:00 - 14:00 y 16:00 - 21:00 | M13: 8 | N13: 11:00 - 14:00 y 16:00 - 21:00 | O13: 8 | P13: =SUM(C13+E13+G13+I13+K13+M13+O13) -> 56 | Q13: Ha pedido modificar sus entradas para abarcar una hora antes la venta
A14: ECI HUELVA | B14: 10:30 - 13:30 y 16:00 - 21:00 | C14: 8 | D14: 10:30 - 13:30 y 16:00 - 21:00 | E14: 8 | F14: 10:30 - 13:30 y 16:00 - 21:00 | G14: 0 | H14: 10:30 - 13:30 y 16:00 - 21:00 | I14: 8 | J14: 10:00 - 14:00 y 17:00 - 21:00 | K14: 8 | L14: 10:00 - 14:00 y 17:00 - 21:00 | M14: 8 | N14: LIBRE | O14: 0 | P14: =SUM(C14+E14+G14+I14+K14+M14+O14) -> 40
A15: ECI A CORUÑA | B15: 12:00 - 14:00 y 15:00 - 21:00 | C15: 8 | D15: 12:00 - 14:00 y 15:00 - 21:00 | E15: 8 | F15: 12:00 - 14:00 y 15:00 - 21:00 | G15: 8 | H15: 12:00 - 14:00 y 15:00 - 21:00 | I15: 8 | J15: 12:00 - 14:00 y 15:00 - 21:00 | K15: 8 | L15: 12:00 - 14:00 y 15:00 - 21:00 | M15: 8 | N15: LIBRE | O15: 0 | P15: =SUM(C15+E15+G15+I15+K15+M15+O15) -> 48
A16: ECI PAMPLONA | B16: 11:00 - 14:00 y 16:00 - 21:00 | C16: 8 | D16: 11:00 - 14:00 y 16:00 - 21:00 | E16: 8 | F16: 11:00 - 16:00 y 18:00 a 21:00 | G16: 8 | H16: 11:00 - 14:00 y 16:00 - 21:00 | I16: 8 | J16: 11:00 - 14:00 y 16:00 - 21:00 | K16: 8 | L16: 11:00 - 14:00 y 16:00 - 21:00 | M16: 8 | N16: LIBRE | O16: 0 | P16: =SUM(C16+E16+G16+I16+K16+M16+O16) -> 48 | Q16: Tiene examen nacionalidad 16:30 (26/11/25)
A17: ECI SAN JOSÉ DE VALDERAS | B17: LIBRE | C17: 0 | D17: 12:00 - 15:00 y 16:00 - 21:00 | E17: 8 | F17: 12:00 - 15:00 y 16:00 - 21:00 | G17: 8 | H17: 12:00 - 15:00 y 16:00 - 21:00 | I17: 8 | J17: 12:00 - 15:00 y 16:00 - 21:00 | K17: 8 | L17: 12:00 - 15:00 y 16:00 - 21:00 | M17: 8 | N17: 12:00 - 15:00 y 16:00 - 21:00 | O17: 8 | P17: =SUM(C17+E17+G17+I17+K17+M17+O17) -> 48
A19: W49
A20: CENTRO | B20: Lunes 1 | D20: Martes 2 | F20: Miercoles 3 | H20: Jueves 4 | J20: Viernes 5 | L20: Sabado 6 | N20: Domingo 7 | P20: total | Q20: Comentarios
A21: ECI LEÓN | C21: 0 | E21: 0 | G21: 0 | H21: 12:00 - 14:00 y 15:00 - 21:00 | I21: 8 | J21: 12:00 - 14:00 y 15:00 - 21:00 | K21: 8 | L21: 12:00 - 14:00 y 15:00 - 21:00 | M21: 8 | N21: LIBRE | O21: =VLOOKUP(N21, 'horarios BBDD'!$A:$B,2,0) -> 0 | P21: =O21+M21+K21+I21+G21+E21+C21 -> 24
A22: ECI COSTA MIJAS | B22: 12:00 - 14:00 y 15:00 - 21:00 | C22: 8 | D22: 12:00 - 14:00 y 15:00 - 21:00 | E22: 8 | F22: LIBRE | G22: =VLOOKUP(F22, 'horarios BBDD'!$A:$B,2,0) -> 0 | H22: 12:00 - 14:00 y 15:00 - 21:00 | I22: 8 | J22: 12:00 - 15:00 y 16:00 - 21:00 | K22: 8 | L22: 12:00 - 15:00 y 16:00 - 21:00 | M22: 8 | N22: LIBRE | O22: =VLOOKUP(N22, 'horarios BBDD'!$A:$B,2,0) -> 0 | P22: =O22+M22+K22+I22+G22+E22+C22 -> 40 | Q22: día de libranza modificado por libranza de la competencia
A23: ECI BAHÍA MÁLAGA | B23: 11:00 - 14:00 y 16:00 - 21:00 | C23: 8 | D23: 12:00 - 14:00 y 15:00 - 21:00 | E23: 8 | F23: LIBRE | G23: =VLOOKUP(F23, 'horarios BBDD'!$A:$B,2,0) -> 0 | H23: LIBRE | I23: =VLOOKUP(H23, 'horarios BBDD'!$A:$B,2,0) -> 0 | J23: 11:00 - 14:00 y 16:00 - 21:00 | K23: 8 | L23: LIBRE | M23: 8 | N23: LIBRE | O23: 0 | P23: =O23+M23+K23+I23+G23+E23+C23 -> 32 | Q23: día de libranza modificado por libranza de la competencia
A24: ECI CORNELLÁ | B24: 12:00 - 14:00 y 15:00 - 21:00 | C24: 8 | D24: LIBRE | E24: =VLOOKUP(D24, 'horarios BBDD'!$A:$B,2,0) -> 0 | F24: 12:00 - 14:00 y 15:00 - 21:00 | G24: 8 | H24: LIBRE | I24: =VLOOKUP(H24, 'horarios BBDD'!$A:$B,2,0) -> 0 | J24: 12:00 - 14:00 y 15:00 - 21:00 | K24: 8 | L24: LIBRE | M24: 8 | N24: LIBRE | O24: =VLOOKUP(N24, 'horarios BBDD'!$A:$B,2,0) -> 0 | P24: =O24+M24+K24+I24+G24+E24+C24 -> 32
A25: ECI PLAZA DEL DUQUE | B25: 12:00 - 14:00 y 15:00 - 21:00 | C25: 8 | D25: LIBRE | E25: =VLOOKUP(D25, 'horarios BBDD'!$A:$B,2,0) -> 0 | F25: 12:00 - 14:00 y 15:00 - 21:00 | G25: 8 | H25: LIBRE | I25: =VLOOKUP(H25, 'horarios BBDD'!$A:$B,2,0) -> 0 | J25: 12:00 - 14:00 y 15:00 - 21:00 | K25: 8 | L25: LIBRE | M25: 8 | N25: LIBRE | O25: 0 | P25: =O25+M25+K25+I25+G25+E25+C25 -> 32
A26: ECI TALAVERA | B26: 12:00 - 14:00 y 15:00 - 21:00 | C26: 8 | D26: 12:00 - 14:00 y 15:00 - 21:00 | E26: 8 | F26: LIBRE | G26: =VLOOKUP(F26, 'horarios BBDD'!$A:$B,2,0) -> 0 | H26: 12:00 - 14:00 y 15:00 - 21:00 | I26: 8 | J26: 12:00 - 14:00 y 15:00 - 21:00 | K26: 8 | L26: LIBRE | M26: 8 | N26: LIBRE | O26: 0 | P26: =O26+M26+K26+I26+G26+E26+C26 -> 40
A27: ECI ZARAGOZA ( SAGASTA) | B27: 12:00 - 14:00 y 15:00 - 21:00 | C27: 8 | D27: LIBRE | E27: =VLOOKUP(D27, 'horarios BBDD'!$A:$B,2,0) -> 0 | F27: 12:00 - 14:00 y 15:00 - 21:00 | G27: 8 | H27: 12:00 - 14:00 y 15:00 - 21:00 | I27: =VLOOKUP(H27, 'horarios BBDD'!$A:$B,2,0) -> 8 | J27: 12:00 - 14:00 y 15:00 - 21:00 | K27: 8 | L27: 12:00 - 14:00 y 15:00 - 21:00 | M27: 8 | N27: LIBRE | O27: 0 | P27: =O27+M27+K27+I27+G27+E27+C27 -> 40
A28: ECI ÁLCALA DE HENARES | B28: 12:00 - 14:00 y 15:00 - 21:00 | C28: 8 | E28: 0 | G28: 0 | I28: 8 | K28: 8 | M28: 8 | O28: 8 | P28: =O28+M28+K28+I28+G28+E28+C28 -> 40
A29: ECI RONDA CÓRDOBA | B29: 12:00 - 15:00 y 16:00 - 21:00 | C29: 8 | D29: 16:00 -21:00 | E29: 6 | F29: LIBRE | G29: =VLOOKUP(F29, 'horarios BBDD'!$A:$B,2,0) -> 0 | H29: 15:30 -21:00 | I29: 6.5 | J29: 15:30 -21:00 | K29: 6.5 | L29: 12:00 - 15:00 y 16:00 - 21:00 | M29: 8 | N29: LIBRE | O29: =VLOOKUP(N29, 'horarios BBDD'!$A:$B,2,0) -> 0 | P29: =O29+M29+K29+I29+G29+E29+C29 -> 35 | Q29: día de libranza modificado por libranza de la competencia
A30: ECI SALAMANCA | B30: 12:00 - 14:00 y 15:00 - 21:00 | C30: 8 | D30: 12:00 - 14:00 y 15:00 - 21:00 | E30: 8 | F30: LIBRE | G30: =VLOOKUP(F30, 'horarios BBDD'!$A:$B,2,0) -> 0 | H30: LIBRE | I30: =VLOOKUP(H30, 'horarios BBDD'!$A:$B,2,0) -> 0 | J30: 12:00 - 14:00 y 15:00 - 21:00 | K30: 8 | L30: 12:00 - 14:00 y 15:00 - 21:00 | M30: 8 | N30: LIBRE | O30: 0 | P30: =O30+M30+K30+I30+G30+E30+C30 -> 32
A31: ECI GUADALAJARA | B31: 12:00 - 14:00 y 15:00 - 21:00 | C31: 8 | D31: LIBRE | E31: =VLOOKUP(D31, 'horarios BBDD'!$A:$B,2,0) -> 0 | F31: LIBRE | G31: =VLOOKUP(F31, 'horarios BBDD'!$A:$B,2,0) -> 0 | H31: 12:00 - 14:00 y 15:00 - 21:00 | I31: 8 | J31: 12:00 - 14:00 y 15:00 - 21:00 | K31: 8 | L31: 12:00 - 14:00 y 15:00 - 21:00 | M31: 8 | N31: LIBRE | O31: 0 | P31: =O31+M31+K31+I31+G31+E31+C31 -> 32 | Q31: Al final trabaja el festivo
A32: ECI HUELVA | C32: 8 | E32: 8 | G32: 8 | I32: 0 | K32: 8 | L32: LIBRE | M32: 8 | N32: LIBRE | O32: 0 | P32: =O32+M32+K32+I32+G32+E32+C32 -> 40
A33: ECI A CORUÑA | B33: 12:00 - 14:00 y 15:00 - 21:00 | C33: 8 | D33: 12:00 - 14:00 y 15:00 - 21:00 | E33: 8 | F33: LIBRE | G33: =VLOOKUP(F33, 'horarios BBDD'!$A:$B,2,0) -> 0 | H33: 12:00 - 14:00 y 15:00 - 21:00 | I33: 8 | J33: 10:00 - 16:00 | K33: 6 | L33: LIBRE | M33: 8 | N33: LIBRE | O33: 0 | P33: =O33+M33+K33+I33+G33+E33+C33 -> 38 | Q33: Ha pedido modificación en la libranza por temas personales/ Ha pedido un día de vacaciones por temas personales
A34: ECI PAMPLONA | B34: 11:00 - 14:00 y 16:00 - 21:00 | C34: 8 | D34: LIBRE | E34: 0 | F34: LIBRE | G34: 0 | H34: 11:00 - 14:00 y 16:00 - 21:00 | I34: 8 | J34: 11:00 - 14:00 y 16:00 - 21:00 | K34: 8 | L34: 11:00 - 14:00 y 16:00 - 21:00 | M34: 8 | N34: LIBRE | O34: 0 | P34: =O34+M34+K34+I34+G34+E34+C34 -> 32 | Q34: día de libranza modificado por libranza de la competencia
A35: ECI SAN JOSÉ DE VALDERAS | B35: 12:00 - 14:00 y 15:00 - 21:00 | C35: 8 | D35: LIBRE | E35: 0 | F35: LIBRE | G35: 0 | H35: 12:00 - 14:00 y 15:00 - 21:00 | I35: 8 | J35: 12:00 - 14:00 y 15:00 - 21:00 | K35: 8 | L35: 12:00 - 14:00 y 15:00 - 21:00 | M35: 8 | N35: 12:00 - 14:00 y 15:00 - 21:00 | O35: 8 | P35: =O35+M35+K35+I35+G35+E35+C35 -> 40
A38: W50
A39: CENTRO | B39: Lunes 8 | D39: Martes 9 | F39: Miercoles 10 | H39: Jueves 11 | J39: Viernes 12 | L39: Sabado 13 | N39: Domingo 14 | P39: total | Q39: Comentarios
A40: ECI LEÓN | B40: 12:00 - 14:00 y 15:00 - 21:00 | C40: 8 | D40: 12:00 - 14:00 y 15:00 - 21:00 | E40: 8 | F40: LIBRE | G40: 0 | H40: 12:00 - 14:00 y 15:00 - 21:00 | I40: 8 | J40: 12:00 - 14:00 y 15:00 - 21:00 | K40: 8 | L40: 12:00 - 14:00 y 15:00 - 21:00 | M40: 8 | N40: LIBRE | O40: 0 | P40: =O40+M40+K40+I40+G40+E40+C40 -> 40 | S40: =P3+P21+P40 -> 104
A41: ECI COSTA MIJAS | B41: FESTIVO | C41: 0 | D41: 12:00 - 14:00 y 15:00 - 21:00 | E41: 8 | F41: LIBRE | G41: 0 | H41: 12:00 - 15:00 y 16:00 - 21:00 | I41: 8 | J41: 12:00 - 15:00 y 16:00 - 21:00 | K41: 8 | L41: 12:00 - 15:00 y 16:00 - 21:00 | M41: 8 | N41: 12:00 - 15:00 y 16:00 - 21:00 | O41: 8 | P41: =O41+M41+K41+I41+G41+E41+C41 -> 40 | S41: =P4+P22+P41 -> 120
A42: ECI BAHÍA MÁLAGA | B42: FESTIVO | C42: 8 | D42: LIBRE | E42: 0 | F42: 11:00 - 14:00 y 16:00 - 21:00 | G42: 8 | H42: LIBRE | I42: 0 | J42: 11:00 - 14:00 y 16:00 - 21:00 | K42: 8 | L42: 11:00 - 14:00 y 16:00 - 21:00 | M42: 8 | N42: 11:00 - 14:00 y 16:00 - 21:00 | O42: 8 | P42: =O42+M42+K42+I42+G42+E42+C42 -> 40 | Q42: Tiene médico a las 11:30 | S42: =P5+P23+P42 -> 120
A43: ECI CORNELLÁ | B43: FESTIVO | C43: 0 | D43: 12:00 - 14:00 y 15:00 - 21:00 | E43: 8 | F43: 12:00 - 14:00 y 15:00 - 21:00 | G43: 8 | H43: 12:00 - 14:00 y 15:00 - 21:00 | I43: 8 | J43: 12:00 - 14:00 y 15:00 - 21:00 | K43: 8 | L43: 12:00 - 14:00 y 15:00 - 21:00 | M43: 8 | N43: LIBRE | O43: 0 | P43: =O43+M43+K43+I43+G43+E43+C43 -> 40 | S43: =P6+P24+P43 -> 120
...

Sheet ENERO 26
A1: W01
A2: CENTRO | B2: Lunes 29 | D2: Martes 30 | F2: Miercoles 31 | H2: Jueves 01 | J2: Viernes 02 | L2: Sábado 03 | N2: Domingo 04 | P2: total | Q2: COMENTARIOS
A3: ECI LEÓN | B3: 12:00 - 14:00 y 15:00 - 21:00 | C3: 8 | D3: 12:00 - 14:00 y 15:00 - 21:00 | E3: 8 | F3: 10:00 - 14:00 | G3: 4 | H3: FESTIVO | I3: 8 | J3: 12:00 - 14:00 y 15:00 - 21:00 | K3: 8 | L3: 12:00 - 14:00 y 15:00 - 21:00 | M3: 8 | N3: 12:00 - 14:00 y 15:00 - 21:00 | O3: 8 | P3: =C3+E3+G3+I3+K3+M3+O3 -> 52 | Q3: 8H extra
A4: ECI COSTA MIJAS | B4: 17:00- 21:00 | C4: 4 | D4: 12:00 - 14:00 y 15:00 - 21:00 | E4: 8 | F4: LIBRE | G4: 0 | H4: FESTIVO | I4: 8 | J4: 12:00 - 14:00 y 15:00 - 21:00 | K4: 8 | L4: 12:00 - 14:00 y 15:00 - 21:00 | M4: 8 | N4: 12:00 - 15:00 y 16:00 - 21:00 | O4: 8 | P4: =C4+E4+G4+I4+K4+M4+O4 -> 44
A5: ECI BAHÍA MÁLAGA | B5: 11:00 - 14:00 y 16:00 - 21:00 | C5: 8 | D5: 17:00- 21:00 | E5: 4 | F5: LIBRE | G5: 0 | H5: FESTIVO | I5: 8 | J5: 11:00 - 14:00 y 16:00 - 21:00 | K5: 8 | L5: 11:00 - 14:00 y 16:00 - 21:00 | M5: 8 | N5: 11:00 - 14:00 y 16:00 - 21:00 | O5: 8 | P5: =C5+E5+G5+I5+K5+M5+O5 -> 44
A6: ECI CORNELLÁ | B6: 12:00 - 14:00 y 15:00 - 21:00 | C6: 8 | D6: 12:00 - 14:00 y 15:00 - 21:00 | E6: 8 | F6: LIBRE | G6: 0 | H6: FESTIVO | I6: 8 | J6: 12:00 - 14:00 y 15:00 - 21:00 | K6: 8 | L6: 12:00 - 14:00 y 15:00 - 21:00 | M6: 8 | N6: LIBRE | O6: 0 | P6: =C6+E6+G6+I6+K6+M6+O6 -> 40
A7: ECI PLAZA DEL DUQUE | B7: 12:00 - 14:00 y 15:00 - 21:00 | C7: 8 | D7: 12:00 - 14:00 y 15:00 - 21:00 | E7: 8 | F7: 10:00 - 14:00 | G7: 4 | H7: FESTIVO | I7: 8 | J7: 12:00 - 14:00 y 15:00 - 21:00 | K7: 8 | L7: 12:00 - 14:00 y 15:00 - 21:00 | M7: 8 | N7: LIBRE | O7: 0 | P7: =C7+E7+G7+I7+K7+M7+O7 -> 44
A8: ECI TALAVERA | B8: 12:00 - 14:00 y 15:00 - 21:00 | C8: 8 | D8: 12:00 - 14:00 y 15:00 - 21:00 | E8: 8 | F8: 10:00 - 14:00 | G8: 4 | H8: FESTIVO | I8: 0 | J8: 12:00 - 14:00 y 15:00 - 21:00 | K8: 8 | L8: 12:00 - 14:00 y 15:00 - 21:00 | M8: 8 | N8: 12:00 - 14:00 y 15:00 - 21:00 | O8: 8 | P8: =C8+E8+G8+I8+K8+M8+O8 -> 44
A9: ECI ZARAGOZA ( SAGASTA) | B9: 12:00 - 14:00 y 15:00 - 21:00 | C9: 8 | D9: 17:00- 21:00 | E9: 4 | F9: 10:00 - 14:00 | G9: 4 | H9: FESTIVO | I9: 8 | J9: 12:00 - 14:00 y 15:00 - 21:00 | K9: 8 | L9: 12:00 - 14:00 y 15:00 - 21:00 | M9: 8 | N9: 12:00 - 14:00 y 15:00 - 21:00 | O9: 8 | P9: =C9+E9+G9+I9+K9+M9+O9 -> 48 | Q9: 8H extra
A10: ECI ÁLCALA DE HENARES | B10: 12:00 - 14:00 y 15:00 - 21:00 | C10: 8 | D10: 17:00- 21:00 | E10: 4 | F10: LIBRE | G10: 0 | H10: FESTIVO | I10: 8 | J10: 12:00 - 14:00 y 15:00 - 21:00 | K10: 8 | L10: 12:00 - 14:00 y 15:00 - 21:00 | M10: 8 | N10: 12:00 - 14:00 y 15:00 - 21:00 | O10: 8 | P10: =C10+E10+G10+I10+K10+M10+O10 -> 44
A11: ECI RONDA CÓRDOBA | B11: 12:00 - 15:00 y 16:00 - 21:00 | C11: 8 | D11: 12:00 - 15:00 y 16:00 - 21:00 | E11: 8 | F11: 10:00 - 14:00 | G11: 4 | H11: FESTIVO | I11: 8 | J11: 12:00 - 15:00 y 16:00 - 21:00 | K11: 8 | L11: 12:00 - 15:00 y 16:00 - 21:00 | M11: 8 | N11: LIBRE | O11: 0 | P11: =C11+E11+G11+I11+K11+M11+O11 -> 44
A12: ECI SALAMANCA | B12: 12:00 - 14:00 y 15:00 - 21:00 | C12: 8 | D12: 12:00 - 14:00 y 15:00 - 21:00 | E12: 8 | F12: 10:00 - 14:00 | G12: 4 | H12: FESTIVO | I12: 8 | J12: 12:00 - 14:00 y 15:00 - 21:00 | K12: 8 | L12: 12:00 - 14:00 y 15:00 - 21:00 | M12: 8 | N12: 12:00 - 14:00 y 15:00 - 21:00 | O12: 8 | P12: =C12+E12+G12+I12+K12+M12+O12 -> 52 | Q12: 8H Extra
A13: ECI GUADALAJARA | B13: 12:00 - 14:00 y 15:00 - 21:00 | C13: 8 | D13: 12:00 - 14:00 y 15:00 - 21:00 | E13: 8 | F13: LIBRE | G13: 0 | H13: FESTIVO | I13: 0 | J13: 12:00 - 14:00 y 15:00 - 21:00 | K13: 8 | L13: 12:00 - 14:00 y 15:00 - 21:00 | M13: 8 | N13: 12:00 - 14:00 y 15:00 - 21:00 | O13: 8 | P13: =C13+E13+G13+I13+K13+M13+O13 -> 40
A14: ECI HUELVA | B14: 11:00 - 14:00 y 16:00 - 21:00 | C14: 8 | D14: 10:30 - 13:30 y 16:00 - 21:00 | E14: 8 | F14: 10:00 - 14:00 | G14: 4 | H14: FESTIVO | I14: 8 | J14: 10:00 - 14:00 y 17:00 - 21:00 | K14: 8 | L14: 10:00 - 14:00 y 17:00 - 21:00 | M14: 8 | N14: LIBRE | O14: 0 | P14: =C14+E14+G14+I14+K14+M14+O14 -> 44
A15: ECI A CORUÑA | B15: 12:00 - 14:00 y 15:00 - 21:00 | C15: 8 | D15: 12:00 - 14:00 y 15:00 - 21:00 | E15: 8 | F15: LIBRE | G15: 0 | H15: FESTIVO | I15: 0 | J15: 12:00 - 14:00 y 15:00 - 21:00 | K15: 8 | L15: 12:00 - 14:00 y 15:00 - 21:00 | M15: 8 | N15: 12:00 - 14:00 y 15:00 - 21:00 | O15: 8 | P15: =C15+E15+G15+I15+K15+M15+O15 -> 40
A16: ECI PAMPLONA | B16: 11:00 - 14:00 y 16:00 - 21:00 | C16: 8 | D16: 17:00- 21:00 | E16: 4 | F16: LIBRE | G16: 0 | H16: FESTIVO | I16: 0 | J16: 11:00 - 14:00 y 16:00 - 21:00 | K16: 8 | L16: 11:00 - 14:00 y 16:00 - 21:00 | M16: 8 | N16: 11:00 - 14:00 y 16:00 - 21:00 | O16: 8 | P16: =C16+E16+G16+I16+K16+M16+O16 -> 36
A17: ECI SAN JOSÉ DE VALDERAS | B17: 12:00 - 15:00 y 16:00 - 21:00 | C17: 8 | D17: 17:00- 21:00 | E17: 4 | F17: LIBRE | G17: 0 | H17: FESTIVO | I17: 8 | J17: 12:00 - 15:00 y 16:00 - 21:00 | K17: 8 | L17: 12:00 - 15:00 y 16:00 - 21:00 | M17: 8 | N17: 12:00 - 14:00 y 15:00 - 21:00 | O17: 8 | P17: =C17+E17+G17+I17+K17+M17+O17 -> 44
A19: W02
A20: CENTRO | B20: Lunes 05 | D20: Martes 06 | F20: Miercoles 07 | H20: Jueves 08 | J20: Viernes 09 | L20: Sábado 10 | N20: Domingo 11 | P20: total | Q20: COMENTARIOS
A21: ECI LEÓN | B21: 12:00 - 14:00 y 15:00 - 21:00 | C21: 8 | D21: FESTIVO | E21: 8 | F21: LIBRE | G21: 0 | H21: LIBRE | I21: 0 | J21: 12:00 - 14:00 y 15:00 - 21:00 | K21: 8 | L21: 12:00 - 14:00 y 15:00 - 21:00 | M21: 8 | N21: 12:00 - 14:00 y 15:00 - 21:00 | O21: 8 | P21: =C21+E21+G21+I21+K21+M21+O21 -> 40
A22: ECI COSTA MIJAS | D22: FESTIVO | E22: 0 | H22: 12:00 - 14:00 y 15:00 - 21:00 | I22: 8 | J22: 12:00 - 14:00 y 15:00 - 21:00 | K22: 8 | L22: 12:00 - 14:00 y 15:00 - 21:00 | M22: 8 | N22: LIBRE | O22: 0 | P22: =C22+E22+G22+I22+K22+M22+O22 -> 24 | Q22: Incorporación 08/01
A23: ECI BAHÍA MÁLAGA | B23: 11:00 - 14:00 y 16:00 - 21:00 | C23: 8 | D23: FESTIVO | E23: 8 | F23: LIBRE | G23: 0 | H23: 11:00 - 14:00 y 16:00 - 21:00 | I23: 8 | J23: 11:00 - 14:00 y 16:00 - 21:00 | K23: 8 | L23: 11:00 - 14:00 y 16:00 - 21:00 | M23: 8 | N23: LIBRE | O23: 0 | P23: =C23+E23+G23+I23+K23+M23+O23 -> 40
A24: ECI CORNELLÁ | B24: 12:00 - 14:00 y 15:00 - 21:00 | C24: 8 | D24: FESTIVO | E24: 0 | F24: 12:00 - 14:00 y 15:00 - 21:00 | G24: 8 | H24: 12:00 - 14:00 y 15:00 - 21:00 | I24: 8 | J24: 12:00 - 14:00 y 15:00 - 21:00 | K24: 8 | L24: 12:00 - 14:00 y 15:00 - 21:00 | M24: 8 | N24: LIBRE | O24: 0 | P24: =C24+E24+G24+I24+K24+M24+O24 -> 40
A25: ECI PLAZA DEL DUQUE | B25: 12:00 - 14:00 y 15:00 - 21:00 | C25: 8 | D25: FESTIVO | E25: 8 | F25: 12:00 - 14:00 y 15:00 - 21:00 | G25: 8 | H25: LIBRE | I25: 0 | J25: 12:00 - 14:00 y 15:00 - 21:00 | K25: 8 | L25: 12:00 - 14:00 y 15:00 - 21:00 | M25: 8 | N25: LIBRE | O25: 0 | P25: =C25+E25+G25+I25+K25+M25+O25 -> 40
A26: ECI TALAVERA | B26: 12:00 - 14:00 y 15:00 - 21:00 | C26: 8 | D26: FESTIVO | E26: 0 | F26: 12:00 - 14:00 y 15:00 - 21:00 | G26: 8 | H26: LIBRE | I26: 0 | J26: 12:00 - 14:00 y 15:00 - 21:00 | K26: 8 | L26: 12:00 - 14:00 y 15:00 - 21:00 | M26: 8 | N26: 12:00 - 14:00 y 15:00 - 21:00 | O26: 8 | P26: =C26+E26+G26+I26+K26+M26+O26 -> 40
A27: ECI ZARAGOZA ( SAGASTA) | B27: 12:00 - 14:00 y 15:00 - 21:00 | C27: 8 | D27: FESTIVO | E27: 0 | F27: LIBRE | G27: 0 | H27: 12:00 - 14:00 y 15:00 - 21:00 | I27: 8 | J27: 12:00 - 14:00 y 15:00 - 21:00 | K27: 8 | L27: 12:00 - 14:00 y 15:00 - 21:00 | M27: 8 | N27: 12:00 - 14:00 y 15:00 - 21:00 | O27: 8 | P27: =C27+E27+G27+I27+K27+M27+O27 -> 40
A28: ECI ÁLCALA DE HENARES | B28: 12:00 - 14:00 y 15:00 - 21:00 | C28: 8 | D28: FESTIVO | E28: 0 | F28: 12:00 - 14:00 y 15:00 - 21:00 | G28: 8 | H28: LIBRE | I28: 0 | J28: 12:00 - 14:00 y 15:00 - 21:00 | K28: 8 | L28: 12:00 - 14:00 y 15:00 - 21:00 | M28: 8 | N28: 12:00 - 14:00 y 15:00 - 21:00 | O28: 8 | P28: =C28+E28+G28+I28+K28+M28+O28 -> 40
A29: ECI RONDA CÓRDOBA | B29: 12:00 - 15:00 y 16:00 - 21:00 | C29: 8 | D29: FESTIVO | E29: 0 | F29: 12:00 - 15:00 y 16:00 - 21:00 | G29: 8 | H29: 12:00 - 15:00 y 16:00 - 21:00 | I29: 8 | J29: 12:00 - 15:00 y 16:00 - 21:00 | K29: 8 | L29: 12:00 - 15:00 y 16:00 - 21:00 | M29: 8 | N29: LIBRE | O29: 0 | P29: =C29+E29+G29+I29+K29+M29+O29 -> 40
A30: ECI SALAMANCA | B30: 12:00 - 14:00 y 15:00 - 21:00 | C30: 8 | D30: FESTIVO | E30: 8 | F30: LIBRE | G30: 0 | H30: 12:00 - 14:00 y 15:00 - 21:00 | I30: 8 | J30: 12:00 - 14:00 y 15:00 - 21:00 | K30: 8 | L30: 12:00 - 14:00 y 15:00 - 21:00 | M30: 8 | N30: 12:00 - 14:00 y 15:00 - 21:00 | O30: 8 | P30: =C30+E30+G30+I30+K30+M30+O30 -> 48 | Q30: 8H extra
A31: ECI GUADALAJARA | B31: 12:00 - 14:00 y 15:00 - 21:00 | C31: 8 | D31: FESTIVO | E31: 0 | F31: LIBRE | G31: 0 | H31: 12:00 - 14:00 y 15:00 - 21:00 | I31: 8 | J31: 12:00 - 14:00 y 15:00 - 21:00 | K31: 8 | L31: 12:00 - 14:00 y 15:00 - 21:00 | M31: 8 | N31: 12:00 - 14:00 y 15:00 - 21:00 | O31: 8 | P31: =C31+E31+G31+I31+K31+M31+O31 -> 40
A32: ECI HUELVA | B32: 11:00 - 14:00 y 16:00 - 21:00 | C32: 8 | D32: FESTIVO | E32: 8 | F32: LIBRE | G32: 0 | H32: 11:00 - 14:00 y 16:00 - 21:00 | I32: 8 | J32: 11:00 - 14:00 y 16:00 - 21:00 | K32: 8 | L32: 11:00 - 14:00 y 16:00 - 21:00 | M32: 8 | N32: LIBRE | O32: 0 | P32: =C32+E32+G32+I32+K32+M32+O32 -> 40
A33: ECI A CORUÑA | D33: FESTIVO | H33: 12:00 - 14:00 y 15:00 - 21:00 | I33: 8 | J33: 12:00 - 14:00 y 15:00 - 21:00 | K33: 8 | L33: 12:00 - 14:00 y 15:00 - 21:00 | M33: 8 | N33: 12:00 - 14:00 y 15:00 - 21:00 | O33: 8 | P33: =C33+E33+G33+I33+K33+M33+O33 -> 32 | Q33: Incorporación 08/01
A34: ECI PAMPLONA | B34: 11:00 - 14:00 y 16:00 - 21:00 | C34: 8 | D34: FESTIVO | E34: 0 | F34: 11:00 - 14:00 y 16:00 - 21:00 | G34: 8 | H34: 11:00 - 14:00 y 16:00 - 21:00 | I34: 8 | J34: 11:00 - 14:00 y 16:00 - 21:00 | K34: 8 | L34: 11:00 - 14:00 y 16:00 - 21:00 | M34: 8 | N34: LIBRE | O34: 0 | P34: =C34+E34+G34+I34+K34+M34+O34 -> 40
A35: ECI SAN JOSÉ DE VALDERAS | B35: 12:00 - 15:00 y 16:00 - 21:00 | C35: 8 | D35: FESTIVO | E35: 0 | F35: 12:00 - 15:00 y 16:00 - 21:00 | G35: 8 | H35: LIBRE | I35: 0 | J35: 12:00 - 15:00 y 16:00 - 21:00 | K35: 8 | L35: 12:00 - 15:00 y 16:00 - 21:00 | M35: 8 | N35: 12:00 - 15:00 y 16:00 - 21:00 | O35: 8 | P35: =C35+E35+G35+I35+K35+M35+O35 -> 40
A37: W03
A38: CENTRO | B38: Lunes 12 | D38: Martes 13 | F38: Miercoles 14 | H38: Jueves 15 | J38: Viernes 16 | L38: Sábado 17 | N38: Domingo 18 | P38: total | Q38: COMENTARIOS
A39: ECI LEÓN | B39: 12:00 - 14:00 y 15:00 - 21:00 | C39: 8 | D39: 12:00 - 14:00 y 15:00 - 21:00 | E39: 8 | F39: LIBRE | G39: 0 | H39: 12:00 - 14:00 y 15:00 - 21:00 | I39: 8 | J39: 12:00 - 14:00 y 15:00 - 21:00 | K39: 8 | L39: 12:00 - 14:00 y 15:00 - 21:00 | M39: 8 | N39: LIBRE | O39: 0 | P39: =C39+E39+G39+I39+K39+M39+O39 -> 40
A40: ECI COSTA MIJAS | B40: LIBRE | C40: 0 | D40: 12:00 - 14:00 y 15:00 - 21:00 | E40: 8 | F40: 12:00 - 14:00 y 15:00 - 21:00 | G40: 8 | H40: 12:00 - 14:00 y 15:00 - 21:00 | I40: 8 | J40: 12:00 - 14:00 y 15:00 - 21:00 | K40: 8 | L40: 12:00 - 14:00 y 15:00 - 21:00 | M40: 8 | N40: LIBRE | O40: 0 | P40: =C40+E40+G40+I40+K40+M40+O40 -> 40
A41: ECI BAHÍA MÁLAGA | B41: 11:00 - 14:00 y 16:00 - 21:00 | C41: 8 | D41: 11:00 - 14:00 y 16:00 - 21:00 | E41: 8 | F41: LIBRE | G41: 0 | H41: 11:00 - 14:00 y 16:00 - 21:00 | I41: 8 | J41: 11:00 - 14:00 y 16:00 - 21:00 | K41: 8 | L41: 11:00 - 14:00 y 16:00 - 21:00 | M41: 8 | N41: LIBRE | O41: 0 | P41: =C41+E41+G41+I41+K41+M41+O41 -> 40
A42: ECI CORNELLÁ | B42: LIBRE | C42: 0 | D42: 12:00 - 14:00 y 15:00 - 21:00 | E42: 8 | F42: 12:00 - 14:00 y 15:00 - 21:00 | G42: 8 | H42: 12:00 - 14:00 y 15:00 - 21:00 | I42: 8 | J42: 12:00 - 14:00 y 15:00 - 21:00 | K42: 8 | L42: 12:00 - 14:00 y 15:00 - 21:00 | M42: 8 | N42: LIBRE | O42: 0 | P42: =C42+E42+G42+I42+K42+M42+O42 -> 40 | Q42: BAJA 13/01
...

Sheet FEB 2026
A1: W06
A2: CENTRO | B2: 46055 | D2: 46056 | F2: 46057 | H2: 46058 | J2: 46059 | L2: 46060 | N2: 46061 | P2: total | Q2: COMENTARIOS
A3: ECI LEÓN | B3: 12:00 - 14:00 y 15:00 - 21:00 | C3: 8 | D3: 12:00 - 14:00 y 15:00 - 21:00 | E3: 8 | F3: LIBRE | G3: 0 | H3: 12:00 - 14:00 y 15:00 - 21:00 | I3: 8 | J3: 12:00 - 14:00 y 15:00 - 21:00 | K3: 8 | L3: 12:00 - 14:00 y 15:00 - 21:00 | M3: 8 | N3: LIBRE | O3: 0 | P3: =C3+E3+G3+I3+K3+M3+O3 -> 40
A4: ECI COSTA MIJAS | B4: LIBRE | C4: 0 | D4: 12:00 - 14:00 y 15:00 - 21:00 | E4: 8 | F4: 12:00 - 14:00 y 15:00 - 21:00 | G4: 8 | H4: 12:00 - 14:00 y 15:00 - 21:00 | I4: 8 | J4: 12:00 - 14:00 y 15:00 - 21:00 | K4: 8 | L4: 12:00 - 14:00 y 15:00 - 21:00 | M4: 8 | N4: LIBRE | O4: 0 | P4: =C4+E4+G4+I4+K4+M4+O4 -> 40
A5: ECI BAHÍA MÁLAGA | B5: 11:00 - 14:00 y 16:00 - 21:00 | C5: 8 | D5: 11:00 - 14:00 y 16:00 - 21:00 | E5: 8 | F5: LIBRE | G5: 0 | H5: VACACIONES | I5: 0 | J5: 11:00 - 14:00 y 16:00 - 21:00 | K5: 8 | L5: 11:00 - 14:00 y 16:00 - 21:00 | M5: 8 | N5: LIBRE | O5: 0 | P5: =C5+E5+G5+I5+K5+M5+O5 -> 32
A6: ECI CORNELLÁ | B6: 12:00 - 14:00 y 15:00 - 21:00 | C6: 8 | D6: 12:00 - 14:00 y 15:00 - 21:00 | E6: 8 | F6: LIBRE | G6: 0 | H6: 12:00 - 14:00 y 15:00 - 21:00 | I6: 8 | J6: 12:00 - 14:00 y 15:00 - 21:00 | K6: 8 | L6: 12:00 - 14:00 y 15:00 - 21:00 | M6: 8 | N6: LIBRE | O6: 0 | P6: =C6+E6+G6+I6+K6+M6+O6 -> 40
A7: ECI PLAZA DEL DUQUE | B7: LIBRE | C7: 0 | D7: 12:00 - 14:00 y 15:00 - 21:00 | E7: 8 | F7: 12:00 - 14:00 y 15:00 - 21:00 | G7: 8 | H7: 12:00 - 14:00 y 15:00 - 21:00 | I7: 8 | J7: 12:00 - 14:00 y 15:00 - 21:00 | K7: 8 | L7: 12:00 - 14:00 y 15:00 - 21:00 | M7: 8 | N7: LIBRE | O7: 0 | P7: =C7+E7+G7+I7+K7+M7+O7 -> 40 | Q7: Alerta roja en Andalucía
A8: ECI TALAVERA | B8: 12:00 - 14:00 y 15:00 - 21:00 | C8: 8 | D8: 12:00 - 14:00 y 15:00 - 21:00 | E8: 8 | F8: LIBRE | G8: 0 | H8: 12:00 - 14:00 y 15:00 - 21:00 | I8: 8 | J8: 12:00 - 14:00 y 15:00 - 21:00 | K8: 8 | L8: 12:00 - 14:00 y 15:00 - 21:00 | M8: 8 | N8: LIBRE | O8: 0 | P8: =C8+E8+G8+I8+K8+M8+O8 -> 40
A9: ECI ZARAGOZA ( SAGASTA) | B9: 12:00 - 14:00 y 15:00 - 21:00 | C9: 8 | D9: LIBRE | E9: 0 | F9: 12:00 - 14:00 y 15:00 - 21:00 | G9: 8 | H9: 12:00 - 14:00 y 15:00 - 21:00 | I9: 8 | J9: 12:00 - 14:00 y 15:00 - 21:00 | K9: 8 | L9: 12:00 - 14:00 y 15:00 - 21:00 | M9: 8 | N9: LIBRE | O9: 0 | P9: =C9+E9+G9+I9+K9+M9+O9 -> 40
A10: ECI ÁLCALA DE HENARES | B10: LIBRE | C10: 0 | D10: LIBRE | E10: 0 | F10: 12:00 - 14:00 y 15:00 - 21:00 | G10: 8 | H10: 12:00 - 14:00 y 15:00 - 21:00 | I10: 8 | J10: 12:00 - 14:00 y 15:00 - 21:00 | K10: 8 | L10: 12:00 - 14:00 y 15:00 - 21:00 | M10: 8 | N10: 12:00 - 14:00 y 15:00 - 21:00 | O10: 8 | P10: =C10+E10+G10+I10+K10+M10+O10 -> 40 | Q10: Se incorpora 04/02
A11: ECI RONDA CÓRDOBA | B11: LIBRE | C11: 0 | D11: 12:00 - 15:00 y 16:00 - 21:00 | E11: 8 | F11: 12:00 - 15:00 y 16:00 - 21:00 | G11: 8 | H11: 12:00 - 15:00 y 16:00 - 21:00 | I11: 8 | J11: 12:00 - 15:00 y 16:00 - 21:00 | K11: 8 | L11: 12:00 - 15:00 y 16:00 - 21:00 | M11: 8 | N11: LIBRE | O11: 0 | P11: =C11+E11+G11+I11+K11+M11+O11 -> 40 | Q11: robo, entrará más tarde
A12: ECI SALAMANCA | B12: 12:00 - 14:00 y 15:00 - 21:00 | C12: 8 | D12: 12:00 - 14:00 y 15:00 - 21:00 | E12: 8 | F12: LIBRE | G12: 0 | H12: VACACIONES | I12: 0 | J12: VACACIONES | K12: 0 | L12: VACACIONES | M12: 0 | N12: LIBRE | O12: 0 | P12: =C12+E12+G12+I12+K12+M12+O12 -> 16
A13: ECI GUADALAJARA | B13: LIBRE | C13: 0 | D13: 12:00 - 14:00 y 15:00 - 21:00 | E13: 8 | F13: 12:00 - 14:00 y 15:00 - 21:00 | G13: 8 | H13: 12:00 - 14:00 y 15:00 - 21:00 | I13: 8 | J13: 12:00 - 14:00 y 15:00 - 21:00 | K13: 8 | L13: 12:00 - 14:00 y 15:00 - 21:00 | M13: 8 | N13: LIBRE | O13: 0 | P13: =C13+E13+G13+I13+K13+M13+O13 -> 40
A14: ECI HUELVA | B14: 11:00 - 14:00 y 16:00 - 21:00 | C14: 8 | D14: 11:00 - 14:00 y 16:00 - 21:00 | E14: 8 | F14: LIBRE | G14: 0 | H14: 11:00 - 14:00 y 16:00 - 21:00 | I14: 8 | J14: 11:00 - 14:00 y 16:00 - 21:00 | K14: 8 | L14: 11:00 - 14:00 y 16:00 - 21:00 | M14: 8 | N14: LIBRE | O14: 0 | P14: =C14+E14+G14+I14+K14+M14+O14 -> 40
A15: ECI A CORUÑA | B15: 12:00 - 14:00 y 15:00 - 21:00 | C15: 8 | D15: LIBRE | E15: 0 | F15: 12:00 - 14:00 y 15:00 - 21:00 | G15: 8 | H15: 12:00 - 14:00 y 15:00 - 21:00 | I15: 8 | J15: 12:00 - 14:00 y 15:00 - 21:00 | K15: 8 | L15: 12:00 - 14:00 y 15:00 - 21:00 | M15: 8 | N15: LIBRE | O15: 0 | P15: =C15+E15+G15+I15+K15+M15+O15 -> 40
A16: ECI PAMPLONA | B16: VACACIONES | D16: LIBRE | E16: 0 | F16: VACACIONES | G16: 0 | H16: 11:00 - 14:00 y 16:00 - 21:00 | I16: 8 | J16: 11:00 - 14:00 y 16:00 - 21:00 | K16: 8 | L16: 11:00 - 14:00 y 16:00 - 21:00 | M16: 8 | N16: LIBRE | O16: 0 | P16: =C16+E16+G16+I16+K16+M16+O16 -> 24
A17: ECI SAN JOSÉ DE VALDERAS | B17: LIBRE | C17: 0 | D17: LIBRE | E17: 0 | F17: 12:00 - 15:00 y 16:00 - 21:00 | G17: 8 | H17: VACACIONES | I17: 0 | J17: 12:00 - 15:00 y 16:00 - 21:00 | K17: 8 | L17: 12:00 - 15:00 y 16:00 - 21:00 | M17: 8 | N17: 12:00 - 15:00 y 16:00 - 21:00 | O17: 8 | P17: =C17+E17+G17+I17+K17+M17+O17 -> 32
A19: W07
A20: CENTRO | B20: 46062 | D20: 46063 | F20: Miercoles 11/02/26 | H20: 46065 | J20: 46066 | L20: 46067 | N20: 46068 | P20: total | Q20: COMENTARIOS
A21: ECI LEÓN | B21: 12:00 - 14:00 y 15:00 - 21:00 | C21: 8 | D21: 12:00 - 14:00 y 15:00 - 21:00 | E21: 8 | F21: 12:00 - 14:00 y 15:00 - 21:00 | G21: 8 | H21: LIBRE | I21: 0 | J21: 12:00 - 14:00 y 15:00 - 21:00 | K21: 8 | L21: 12:00 - 14:00 y 15:00 - 21:00 | M21: 8 | N21: LIBRE | O21: 0 | P21: =C3+E3+G3+I3+K3+M3+O3 -> 40 | Q21: Modificacion de día libre por formadores
A22: ECI COSTA MIJAS | B22: LIBRE | C22: 0 | D22: 12:00 - 14:00 y 15:00 - 21:00 | E22: 8 | F22: 12:00 - 14:00 y 15:00 - 21:00 | G22: 8 | H22: 12:00 - 14:00 y 15:00 - 21:00 | I22: 8 | J22: 12:00 - 14:00 y 15:00 - 21:00 | K22: 8 | L22: 12:00 - 14:00 y 15:00 - 21:00 | M22: 8 | N22: LIBRE | O22: 0 | P22: =C4+E4+G4+I4+K4+M4+O4 -> 40
A23: ECI BAHÍA MÁLAGA | B23: 11:00 - 14:00 y 16:00 - 21:00 | C23: 8 | D23: 11:00 - 14:00 y 16:00 - 21:00 | E23: 8 | F23: LIBRE | G23: 0 | H23: 11:00 - 14:00 y 16:00 - 21:00 | I23: 8 | J23: 11:00 - 14:00 y 16:00 - 21:00 | K23: 8 | L23: 11:00 - 14:00 y 16:00 - 21:00 | M23: 8 | N23: LIBRE | O23: 0 | P23: =C23+E23+I23+K23+M23+O23 -> 40
A24: ECI CORNELLÁ | B24: 12:00 - 14:00 y 15:00 - 21:00 | C24: 8 | D24: 12:00 - 14:00 y 15:00 - 21:00 | E24: 8 | F24: LIBRE | G24: 0 | H24: 12:00 - 14:00 y 15:00 - 21:00 | I24: 8 | J24: 12:00 - 14:00 y 15:00 - 21:00 | K24: 8 | L24: 12:00 - 14:00 y 15:00 - 21:00 | M24: 8 | N24: LIBRE | O24: 0 | P24: =C6+E6+G6+I6+K6+M6+O6 -> 40 | Q24: Alerta roja
A25: ECI PLAZA DEL DUQUE | B25: 12:00 - 14:00 y 15:00 - 21:00 | C25: 8 | D25: LIBRE | E25: 0 | F25: 12:00 - 14:00 y 15:00 - 21:00 | G25: 8 | H25: 12:00 - 14:00 y 15:00 - 21:00 | I25: 8 | J25: 12:00 - 14:00 y 15:00 - 21:00 | K25: 8 | L25: 12:00 - 14:00 y 15:00 - 21:00 | M25: 8 | N25: LIBRE | O25: 0 | P25: =C7+E7+G7+I7+K7+M7+O7 -> 40
A26: ECI TALAVERA | B26: 12:00 - 14:00 y 15:00 - 21:00 | C26: 8 | D26: 12:00 - 14:00 y 15:00 - 21:00 | E26: 8 | F26: LIBRE | G26: 0 | H26: 16:00 - 21:00 | I26: 5 | J26: 12:00 - 14:00 y 15:00 - 21:00 | K26: 8 | L26: 12:00 - 14:00 y 15:00 - 21:00 | M26: 8 | N26: LIBRE | O26: 0 | P26: =C8+E8+G8+I8+K8+M8+O8 -> 40
A27: ECI ZARAGOZA ( SAGASTA) | B27: 12:00 - 14:00 y 15:00 - 21:00 | C27: 8 | D27: LIBRE | E27: 0 | F27: 12:00 - 14:00 y 15:00 - 21:00 | G27: 8 | H27: 12:00 - 14:00 y 15:00 - 21:00 | I27: 8 | J27: 12:00 - 14:00 y 15:00 - 21:00 | K27: 8 | L27: 12:00 - 14:00 y 15:00 - 21:00 | M27: 8 | N27: LIBRE | O27: 0 | P27: =C9+E9+G9+I9+K9+M9+O9 -> 40
A28: ECI ÁLCALA DE HENARES | B28: LIBRE | C28: 0 | D28: LIBRE | E28: 0 | F28: 12:00 - 14:00 y 15:00 - 21:00 | G28: 8 | H28: 12:00 - 14:00 y 15:00 - 21:00 | I28: 8 | J28: 12:00 - 14:00 y 15:00 - 21:00 | K28: 8 | L28: 12:00 - 14:00 y 15:00 - 21:00 | M28: 8 | N28: 12:00 - 14:00 y 15:00 - 21:00 | O28: 8 | P28: =C10+E10+G10+I10+K10+M10+O10 -> 40
A29: ECI RONDA CÓRDOBA | B29: LIBRE | C29: 0 | D29: 12:00 - 15:00 y 16:00 - 21:00 | E29: 8 | F29: 12:00 - 15:00 y 16:00 - 21:00 | G29: 8 | H29: 12:00 - 15:00 y 16:00 - 21:00 | I29: 8 | J29: 12:00 - 15:00 y 16:00 - 21:00 | K29: 8 | L29: 12:00 - 15:00 y 16:00 - 21:00 | M29: 8 | N29: LIBRE | O29: 0 | P29: =C11+E11+G11+I11+K11+M11+O11 -> 40
A30: ECI SALAMANCA | B30: 12:00 - 14:00 y 15:00 - 21:00 | C30: 8 | D30: 16:00 – 21:00 | E30: 5 | F30: 16:00 – 21:00 | G30: 5 | H30: 15:00 – 21:00 | I30: 6 | J30: 12:00 - 14:00 y 15:00 - 21:00 | K30: 8 | L30: 12:00 - 14:00 y 15:00 - 21:00 | M30: 8 | N30: LIBRE | O30: 0 | P30: =C30+E30+G30+I30+K30+M30+O30 -> 40
A31: ECI GUADALAJARA | B31: LIBRE | C31: 0 | D31: 12:00 - 14:00 y 15:00 - 21:00 | E31: 8 | F31: 12:00 - 14:00 y 15:00 - 21:00 | G31: 8 | H31: 12:00 - 14:00 y 15:00 - 21:00 | I31: 8 | J31: 12:00 - 14:00 y 15:00 - 21:00 | K31: 8 | L31: 12:00 - 14:00 y 15:00 - 21:00 | M31: 8 | N31: LIBRE | O31: 0 | P31: =C13+E13+G13+I13+K13+M13+O13 -> 40
A32: ECI HUELVA | B32: 11:00 - 14:00 y 16:00 - 21:00 | C32: 8 | D32: 16:00 – 21:00 | E32: 5 | F32: 16:00 – 21:00 | G32: 5 | H32: 15:00 – 21:00 | I32: 6 | J32: 11:00 - 14:00 y 16:00 - 21:00 | K32: 8 | L32: 11:00 - 14:00 y 16:00 - 21:00 | M32: 8 | N32: LIBRE | O32: 0 | P32: =C14+E14+G14+I14+K14+M14+O14 -> 40
A33: ECI A CORUÑA | B33: 12:00 - 14:00 y 15:00 - 21:00 | C33: 8 | D33: LIBRE | E33: 0 | F33: 12:00 - 14:00 y 15:00 - 21:00 | G33: 8 | H33: 12:00 - 14:00 y 15:00 - 21:00 | I33: 8 | J33: 12:00 - 14:00 y 15:00 - 21:00 | K33: 8 | L33: 12:00 - 14:00 y 15:00 - 21:00 | M33: 8 | N33: LIBRE | O33: 0 | P33: =C15+E15+G15+I15+K15+M15+O15 -> 40
A34: ECI PAMPLONA | B34: 11:00 - 14:00 y 16:00 - 21:00 | C34: 8 | D34: LIBRE | E34: 0 | F34: 11:00 - 14:00 y 16:00 - 21:00 | G34: 8 | H34: 11:00 - 14:00 y 16:00 - 21:00 | I34: 8 | J34: 11:00 - 14:00 y 16:00 - 21:00 | K34: 8 | L34: 11:00 - 14:00 y 16:00 - 21:00 | M34: 8 | N34: LIBRE | O34: 0 | P34: =C34+E34+G34+I34+K34+M34+O34 -> 40
A35: ECI SAN JOSÉ DE VALDERAS | B35: LIBRE | C35: 0 | D35: LIBRE | E35: 0 | F35: VACACIONES | H35: 12:00 - 15:00 y 16:00 - 21:00 | I35: 8 | J35: 12:00 - 15:00 y 16:00 - 21:00 | K35: 8 | L35: 12:00 - 15:00 y 16:00 - 21:00 | M35: 8 | N35: 12:00 - 15:00 y 16:00 - 21:00 | O35: 8 | P35: =C17+E17+G17+I17+K17+M17+O17 -> 32
A37: W08
A38: CENTRO | B38: 46069 | D38: 46070 | F38: Miercoles 18/02/26 | H38: 46072 | J38: 46073 | L38: 46074 | N38: 46075 | P38: total | Q38: COMENTARIOS
A39: ECI LEÓN | B39: 12:00 - 14:00 y 15:00 - 21:00 | C39: 8 | D39: 12:00 - 14:00 y 15:00 - 21:00 | E39: 8 | F39: LIBRE | G39: 0 | H39: 12:00 - 14:00 y 15:00 - 21:00 | I39: 8 | J39: 12:00 - 14:00 y 15:00 - 21:00 | K39: 8 | L39: 12:00 - 14:00 y 15:00 - 21:00 | M39: 8 | N39: LIBRE | O39: 0 | P39: =C39+E39+G39+I39+M39+O39+K39 -> 40
A40: ECI COSTA MIJAS | B40: LIBRE | C40: 0 | D40: 12:00 - 14:00 y 15:00 - 21:00 | E40: 8 | F40: 12:00 - 14:00 y 15:00 - 21:00 | G40: 8 | H40: 12:00 - 14:00 y 15:00 - 21:00 | I40: 8 | J40: 12:00 - 14:00 y 15:00 - 21:00 | K40: 8 | L40: 12:00 - 14:00 y 15:00 - 21:00 | M40: 8 | N40: LIBRE | O40: 0 | P40: =C40+E40+G40+I40+M40+O40+K40 -> 40
A41: ECI BAHÍA MÁLAGA | B41: 11:00 - 14:00 y 16:00 - 21:00 | C41: 8 | D41: 11:00 - 14:00 y 16:00 - 21:00 | E41: 8 | F41: LIBRE | G41: 0 | H41: 11:00 - 14:00 y 16:00 - 21:00 | I41: 8 | J41: 11:00 - 14:00 y 16:00 - 21:00 | K41: 8 | L41: 11:00 - 14:00 y 16:00 - 21:00 | M41: 8 | N41: LIBRE | O41: 0 | P41: =C41+E41+G41+I41+M41+O41+K41 -> 40
A42: ECI CORNELLÁ | B42: 12:00 - 14:00 y 15:00 - 21:00 | C42: 8 | D42: 12:00 - 14:00 y 15:00 - 21:00 | E42: 8 | F42: LIBRE | G42: 0 | H42: 12:00 - 14:00 y 15:00 - 21:00 | I42: 8 | J42: 12:00 - 14:00 y 15:00 - 21:00 | K42: 8 | L42: 12:00 - 14:00 y 15:00 - 21:00 | M42: 8 | N42: LIBRE | O42: 0 | P42: =C42+E42+G42+I42+M42+O42+K42 -> 40
...

Sheet MAR 2026
A2: W10
A3: CENTRO | B3: 46083 | D3: 46084 | F3: 46085 | H3: 46086 | J3: 46087 | L3: 46088 | N3: 46089 | P3: total
A4: ECI LEÓN | B4: 13:00 - 16:00 y 17:00 - 22:00 | C4: 8 | D4: LIBRE | E4: 0 | F4: 12:00 - 14:00 y 15:00 - 21:00 | G4: 8 | H4: 12:00 - 14:00 y 15:00 - 21:00 | I4: 8 | J4: 12:00 - 14:00 y 15:00 - 21:00 | K4: 8 | L4: 12:00 - 14:00 y 15:00 - 21:00 | M4: 8 | N4: LIBRE | O4: 0 | P4: =C4+E4+G4+I4+K4+M4+O4 -> 40
A5: ECI COSTA MIJAS | B5: LIBRE | C5: 0 | D5: 12:00 - 14:00 y 15:00 - 21:00 | E5: 8 | F5: 12:00 - 14:00 y 15:00 - 21:00 | G5: 8 | H5: 12:00 - 14:00 y 15:00 - 21:00 | I5: 8 | J5: 12:00 - 14:00 y 15:00 - 21:00 | K5: 8 | L5: 12:00 - 14:00 y 15:00 - 21:00 | M5: 8 | N5: LIBRE | O5: 0 | P5: =C5+E5+G5+I5+K5+M5+O5 -> 40
A6: ECI BAHÍA MÁLAGA | B6: 11:00 - 14:00 y 16:00 - 21:00 | C6: 8 | D6: 11:00 - 14:00 y 16:00 - 21:00 | E6: 8 | F6: LIBRE | G6: 0 | H6: 11:00 - 14:00 y 16:00 - 21:00 | I6: 8 | J6: 11:00 - 14:00 y 16:00 - 21:00 | K6: 8 | L6: 11:00 - 14:00 y 16:00 - 21:00 | M6: 8 | N6: LIBRE | O6: 0 | P6: =C6+E6+G6+I6+K6+M6+O6 -> 40
A7: ECI CORNELLÁ | B7: 12:00 - 14:00 y 15:00 - 21:00 | C7: 8 | D7: 12:00 - 14:00 y 15:00 - 21:00 | E7: 8 | F7: LIBRE | G7: 0 | H7: 12:00 - 14:00 y 15:00 - 21:00 | I7: 8 | J7: 12:00 - 14:00 y 15:00 - 21:00 | K7: 8 | L7: 12:00 - 14:00 y 15:00 - 21:00 | M7: 8 | N7: LIBRE | O7: 0 | P7: =C7+E7+G7+I7+K7+M7+O7 -> 40
A8: ECI PLAZA DEL DUQUE | B8: LIBRE | C8: 0 | D8: 12:00 - 14:00 y 15:00 - 21:00 | E8: 8 | F8: 12:00 - 14:00 y 15:00 - 21:00 | G8: 8 | H8: 12:00 - 14:00 y 15:00 - 21:00 | I8: 8 | J8: 12:00 - 14:00 y 15:00 - 21:00 | K8: 8 | L8: 12:00 - 14:00 y 15:00 - 21:00 | M8: 8 | N8: LIBRE | O8: 0 | P8: =C8+E8+G8+I8+K8+M8+O8 -> 40
A9: ECI TALAVERA | B9: 12:00 - 14:00 y 15:00 - 21:00 | C9: 8 | D9: 12:00 - 14:00 y 15:00 - 21:00 | E9: 8 | F9: LIBRE | G9: 0 | H9: 12:00 - 14:00 y 15:00 - 21:00 | I9: 8 | J9: 12:00 - 14:00 y 15:00 - 21:00 | K9: 8 | L9: 12:00 - 14:00 y 15:00 - 21:00 | M9: 8 | N9: LIBRE | O9: 0 | P9: =C9+E9+G9+I9+K9+M9+O9 -> 40
A10: ECI ZARAGOZA ( SAGASTA) | B10: 12:00 - 14:00 y 15:00 - 21:00 | C10: 8 | D10: LIBRE | E10: 0 | F10: 12:00 - 14:00 y 15:00 - 21:00 | G10: 8 | H10: FESTIVO (cierre) | I10: 8 | J10: 12:00 - 14:00 y 15:00 - 21:00 | K10: 8 | L10: 12:00 - 14:00 y 15:00 - 21:00 | M10: 8 | N10: LIBRE | O10: 0 | P10: =C10+E10+G10+I10+K10+M10+O10 -> 40
A11: ECI ÁLCALA DE HENARES | B11: 12:00 - 14:00 y 15:00 - 21:00 | C11: 8 | D11: LIBRE | E11: 0 | F11: LIBRE | G11: 0 | H11: 12:00 - 14:00 y 15:00 - 21:00 | I11: 8 | J11: 12:00 - 14:00 y 15:00 - 21:00 | K11: 8 | L11: 12:00 - 14:00 y 15:00 - 21:00 | M11: 8 | N11: 12:00 - 14:00 y 15:00 - 21:00 | O11: 8 | P11: =C11+E11+G11+I11+K11+M11+O11 -> 40
A12: ECI RONDA CÓRDOBA | B12: LIBRE | C12: 0 | D12: 12:00 - 15:00 y 16:00 - 21:00 | E12: 8 | F12: 12:00 - 15:00 y 16:00 - 21:00 | G12: 8 | H12: 12:00 - 15:00 y 16:00 - 21:00 | I12: 8 | J12: 12:00 - 15:00 y 16:00 - 21:00 | K12: 8 | L12: 12:00 - 15:00 y 16:00 - 21:00 | M12: 8 | N12: LIBRE | O12: 0 | P12: =C12+E12+G12+I12+K12+M12+O12 -> 40
A13: ECI SALAMANCA | B13: 12:00 - 14:00 y 15:00 - 21:00 | C13: 8 | D13: 16:00 – 21:00 | E13: 5 | F13: 16:00 – 21:00 | G13: 5 | H13: 15:00 – 21:00 | I13: 6 | J13: 12:00 - 14:00 y 15:00 - 21:00 | K13: 8 | L13: 12:00 - 14:00 y 15:00 - 21:00 | M13: 8 | N13: LIBRE | O13: 0 | P13: =C13+E13+G13+I13+K13+M13+O13 -> 40
A14: ECI GUADALAJARA | B14: LIBRE | C14: 0 | D14: 12:00 - 14:00 y 15:00 - 21:00 | E14: 8 | F14: 12:00 - 14:00 y 15:00 - 21:00 | G14: 8 | H14: 12:00 - 14:00 y 15:00 - 21:00 | I14: 8 | J14: 12:00 - 14:00 y 15:00 - 21:00 | K14: 8 | L14: 12:00 - 14:00 y 15:00 - 21:00 | M14: 8 | N14: LIBRE | O14: 0 | P14: =C14+E14+G14+I14+K14+M14+O14 -> 40
A15: ECI HUELVA | B15: 12:00 - 14:00 y 15:00 - 21:00 | C15: 8 | D15: 16:00 – 21:00 | E15: 5 | F15: 16:00 – 21:00 | G15: 5 | H15: 15:00 – 21:00 | I15: 6 | J15: 12:00 - 14:00 y 15:00 - 21:00 | K15: 8 | L15: 12:00 - 14:00 y 15:00 - 21:00 | M15: 8 | N15: LIBRE | O15: 0 | P15: =C15+E15+G15+I15+K15+M15+O15 -> 40
... A18: ECI SAN JOSÉ DE VALDERAS | B18: LIBRE | C18: 0 | D18: 12:00 - 15:00 y 16:00 - 21:00 | E18: 8 | F18: LIBRE | G18: 0 | H18: 12:00 - 15:00 y 16:00 - 21:00 | I18: 8 | J18: 12:00 - 15:00 y 16:00 - 21:00 | K18: 8 | L18: 12:00 - 15:00 y 16:00 - 21:00 | M18: 8 | N18: 12:00 - 15:00 y 16:00 - 21:00 | O18: 8 | P18: =C18+E18+G18+I18+K18+M18+O18 -> 40
A21: W11
A22: CENTRO | B22: 46090 | D22: 46091 | F22: Miercoles 11/03/26 | H22: 46093 | J22: 46094 | L22: 46095 | N22: 46096 | P22: total | Q22: COMENTARIOS
A23: ECI LEÓN | B23: 13:00 - 16:00 y 17:00 - 22:00 | C23: 8 | D23: 11:00 - 14:00 y 16:00 - 21:00 | E23: 8 | F23: LIBRE | G23: 0 | H23: 11:00 - 14:00 y 16:00 - 21:00 | I23: 8 | J23: 11:00 - 14:00 y 16:00 - 21:00 | K23: 8 | L23: 11:00 - 14:00 y 16:00 - 21:00 | M23: 8 | N23: LIBRE | O23: 0 | P23: =C23+E23+G23+I23+K23+M23+O23 -> 40
A24: ECI COSTA MIJAS | B24: LIBRE | C24: 0 | D24: 12:00 - 14:00 y 15:00 - 21:00 | E24: 8 | F24: 12:00 - 14:00 y 15:00 - 21:00 | G24: 8 | H24: 12:00 - 14:00 y 15:00 - 21:00 | I24: 8 | J24: 12:00 - 14:00 y 15:00 - 21:00 | K24: 8 | L24: 12:00 - 14:00 y 15:00 - 21:00 | M24: 8 | N24: LIBRE | O24: 0 | P24: =C24+E24+G24+I24+K24+M24+O24 -> 40
A25: ECI BAHÍA MÁLAGA | B25: 11:00 - 14:00 y 16:00 - 21:00 | C25: 8 | D25: 11:00 - 14:00 y 16:00 - 21:00 | E25: 8 | F25: LIBRE | G25: 0 | H25: 11:00 - 14:00 y 16:00 - 21:00 | I25: 8 | J25: 11:00 - 14:00 y 16:00 - 21:00 | K25: 8 | L25: 11:00 - 14:00 y 16:00 - 21:00 | M25: 8 | N25: LIBRE | O25: 0 | P25: =C25+E25+G25+I25+K25+M25+O25 -> 40
A26: ECI CORNELLÁ | B26: 12:00 - 14:00 y 15:00 - 21:00 | C26: 8 | D26: 12:00 - 14:00 y 15:00 - 21:00 | E26: 8 | F26: LIBRE | G26: 0 | H26: 12:00 - 14:00 y 15:00 - 21:00 | I26: 8 | J26: 12:00 - 14:00 y 15:00 - 21:00 | K26: 8 | L26: 12:00 - 14:00 y 15:00 - 21:00 | M26: 8 | N26: LIBRE | O26: 0 | P26: =C26+E26+G26+I26+K26+M26+O26 -> 40
A27: ECI PLAZA DEL DUQUE | B27: LIBRE | C27: 0 | D27: 12:00 - 14:00 y 15:00 - 21:00 | E27: 8 | F27: 12:00 - 14:00 y 15:00 - 21:00 | G27: 8 | H27: 12:00 - 14:00 y 15:00 - 21:00 | I27: 8 | J27: 12:00 - 14:00 y 15:00 - 21:00 | K27: 8 | L27: 12:00 - 14:00 y 15:00 - 21:00 | M27: 8 | N27: LIBRE | O27: 0 | P27: =C27+E27+G27+I27+K27+M27+O27 -> 40 | Q27: Enfermedad
A28: ECI TALAVERA | B28: 12:00 - 14:00 y 15:00 - 21:00 | C28: 8 | D28: 12:00 - 14:00 y 15:00 - 21:00 | E28: 8 | F28: 12:00 - 14:00 y 15:00 - 21:00 | G28: 8 | H28: 12:00 - 14:00 y 15:00 - 21:00 | I28: 8 | J28: 12:00 - 14:00 y 15:00 - 21:00 | K28: 8 | L28: LIBRE | M28: 0 | N28: LIBRE | O28: 0 | P28: =C28+E28+G28+I28+K28+M28+O28 -> 40
A29: ECI ZARAGOZA ( SAGASTA) | B29: 12:00 - 14:00 y 15:00 - 21:00 | C29: 8 | D29: LIBRE | E29: 0 | F29: 12:00 - 14:00 y 15:00 - 21:00 | G29: 8 | H29: 12:00 - 14:00 y 15:00 - 21:00 | I29: 8 | J29: 12:00 - 14:00 y 15:00 - 21:00 | K29: 8 | L29: 12:00 - 14:00 y 15:00 - 21:00 | M29: 8 | N29: LIBRE | O29: 0 | P29: =C29+E29+G29+I29+K29+M29+O29 -> 40
A30: ECI ÁLCALA DE HENARES | B30: 12:00 - 14:00 y 15:00 - 21:00 | C30: 8 | D30: LIBRE | E30: 0 | F30: LIBRE | G30: 0 | H30: 12:00 - 14:00 y 15:00 - 21:00 | I30: 8 | J30: 12:00 - 14:00 y 15:00 - 21:00 | K30: 8 | L30: 12:00 - 14:00 y 15:00 - 21:00 | M30: 8 | N30: 12:00 - 14:00 y 15:00 - 21:00 | O30: 8 | P30: =C30+E30+G30+I30+K30+M30+O30 -> 40
A31: ECI RONDA CÓRDOBA | B31: LIBRE | C31: 0 | D31: 12:00 - 15:00 y 16:00 - 21:00 | E31: 8 | F31: 12:00 - 15:00 y 16:00 - 21:00 | G31: 8 | H31: 12:00 - 15:00 y 16:00 - 21:00 | I31: 8 | J31: 12:00 - 15:00 y 16:00 - 21:00 | K31: 8 | L31: 12:00 - 15:00 y 16:00 - 21:00 | M31: 8 | N31: LIBRE | O31: 0 | P31: =C31+E31+G31+I31+K31+M31+O31 -> 40 | Q31: Accidente de coche
A32: ECI SALAMANCA | B32: 12:00 - 14:00 y 15:00 - 21:00 | C32: 8 | D32: 16:00 – 21:00 | E32: 5 | F32: 16:00 – 21:00 | G32: 5 | H32: 15:00 – 21:00 | I32: 6 | J32: 12:00 - 14:00 y 15:00 - 21:00 | K32: 8 | L32: 12:00 - 14:00 y 15:00 - 21:00 | M32: 8 | N32: 15:00 – 21:00 | O32: 6 | P32: =C32+E32+G32+I32+K32+M32+O32 -> 46
A33: ECI GUADALAJARA | B33: LIBRE | C33: 0 | D33: 12:00 - 14:00 y 15:00 - 21:00 | E33: 8 | F33: 12:00 - 14:00 y 15:00 - 21:00 | G33: 8 | H33: 12:00 - 14:00 y 15:00 - 21:00 | I33: 8 | J33: 12:00 - 14:00 y 15:00 - 21:00 | K33: 8 | L33: 12:00 - 14:00 y 15:00 - 21:00 | M33: 8 | N33: LIBRE | O33: 0 | P33: =C33+E33+G33+I33+K33+M33+O33 -> 40
A34: ECI HUELVA | B34: 12:00 - 14:00 y 15:00 - 21:00 | C34: 8 | D34: 16:00 – 21:00 | E34: 5 | F34: 16:00 – 21:00 | G34: 5 | H34: 15:00 – 21:00 | I34: 6 | J34: 12:00 - 14:00 y 15:00 - 21:00 | K34: 8 | L34: 12:00 - 14:00 y 15:00 - 21:00 | M34: 8 | N34: LIBRE | O34: 0 | P34: =C34+E34+G34+I34+K34+M34+O34 -> 40
A35: ECI A CORUÑA | B35: 12:00 - 14:00 y 15:00 - 21:00 | C35: 8 | D35: LIBRE | E35: 0 | F35: 12:00 - 14:00 y 15:00 - 21:00 | G35: 8 | H35: 12:00 - 14:00 y 15:00 - 21:00 | I35: 8 | J35: 12:00 - 14:00 y 15:00 - 21:00 | K35: 8 | L35: 12:00 - 14:00 y 15:00 - 21:00 | M35: 8 | N35: LIBRE | O35: 0 | P35: =C35+E35+G35+I35+K35+M35+O35 -> 40
A36: ECI PAMPLONA | B36: 11:00 - 14:00 y 16:00 - 21:00 | C36: 8 | D36: 11:00 - 14:00 y 16:00 - 21:00 | E36: 8 | F36: LIBRE | G36: 0 | H36: 11:00 - 14:00 y 16:00 - 21:00 | I36: 8 | J36: 11:00 - 14:00 y 16:00 - 21:00 | K36: 8 | L36: 11:00 - 14:00 y 16:00 - 21:00 | M36: 8 | N36: LIBRE | O36: 0 | P36: =C36+E36+G36+I36+K36+M36+O36 -> 40
A37: ECI SAN JOSÉ DE VALDERAS | B37: LIBRE | C37: 0 | D37: LIBRE | E37: 0 | F37: 12:00 - 15:00 y 16:00 - 21:00 | G37: 8 | H37: 12:00 - 15:00 y 16:00 - 21:00 | I37: 8 | J37: 12:00 - 15:00 y 16:00 - 21:00 | K37: 8 | L37: 12:00 - 15:00 y 16:00 - 21:00 | M37: 8 | N37: 12:00 - 15:00 y 16:00 - 21:00 | O37: 8 | P37: =C37+E37+G37+I37+K37+M37+O37 -> 40
A39: W12
A40: CENTRO | B40: 46097 | D40: 46098 | F40: Miercoles 18/03/26 | H40: 46100 | J40: 46101 | L40: 46102 | N40: 46103 | P40: total
A41: ECI LEÓN | B41: 13:00 - 16:00 y 17:00 - 22:00 | C41: 8 | D41: 11:00 - 14:00 y 16:00 - 21:00 | E41: 8 | F41: LIBRE | G41: 0 | H41: 11:00 - 14:00 y 16:00 - 21:00 | I41: 8 | J41: 11:00 - 14:00 y 16:00 - 21:00 | K41: 8 | L41: 11:00 - 14:00 y 16:00 - 21:00 | M41: 8 | N41: LIBRE | O41: 0 | P41: =C41+E41+G41+I41+K41+M41+O41 -> 40
A42: ECI COSTA MIJAS | B42: LIBRE | C42: 0 | D42: 12:00 - 14:00 y 15:00 - 21:00 | E42: 8 | F42: 12:00 - 14:00 y 15:00 - 21:00 | G42: 8 | H42: 12:00 - 14:00 y 15:00 - 21:00 | I42: 8 | J42: 12:00 - 14:00 y 15:00 - 21:00 | K42: 8 | L42: 12:00 - 14:00 y 15:00 - 21:00 | M42: 8 | N42: LIBRE | O42: 0 | P42: =C42+E42+G42+I42+K42+M42+O42 -> 40
